Workbook
Name KT기변구매가: ADMIN!$F:$F
Name KT모델명: ADMIN!$D:$D
Name KT번이구매가: ADMIN!$E:$E
Name KT요금제: ADMIN!$H:$H
Name LG기변구매가: ADMIN!$V:$V
Name LG모델명: ADMIN!$T:$T
Name LG번이구매가: ADMIN!$U:$U
Name LG요금제: ADMIN!$X:$X
Name SKT기변구매가: ADMIN!$N:$N
Name SKT모델명: ADMIN!$L:$L
Name SKT번이구매가: ADMIN!$M:$M
Name SKT요금제: ADMIN!$P:$P

Sheet 3사 통합
M2: 사용방법 ① 같이 첨부드린 폰트 설치 (압축 해제 후 파일 전체 선택 → 우클릭 → 설치 ② 오프라인 단가일 경우 하단에 O 입력 (알파벳 o 입니다. 대문자 소문자 무관) ③ 가급적이면 행 삭제는 자제 부탁드립니다 (수식 깨짐) 삭제만 하면 상관 없는데, 삭제하고 나서 그냥 추가하면 수식 깨집니다. 가급적 삭제 대신 행 숨기기로 사용해주세요 | U2: ▲ 상단에 + 클릭하면 오프라인 세팅
C4: 오늘의 특가 | D4: SKT | F4: KT | H4: LG U+ | M4: 오프라인 정책만 체크 | O4: SKT | Q4: KT | S4: LG U+
C5: =TEXT(TODAY()," m월 d일") -> 6월 25일
D6: 5GX 프리미엄 | F6: 5G 초이스 스페셜 | H6: 플러스 플랜115 | M6: 요금제 110,000원~ | O6: 5GX 프리미엄 | Q6: 5G 초이스 베이직 | S6: 5G 프리미어 슈퍼
B7: 11만 요금제~
D8: 번이 | E8: 기변 | F8: 번이 | G8: 기변 | H8: 번이 | I8: 기변 | O8: 번이 | P8: 기변 | Q8: 번이 | R8: 기변 | S8: 번이 | T8: 기변
B9: 갤럭시S26 시리즈!!! 행사중!! 가격 문의 먼저 하세요! | M9: 갤럭시S26 시리즈!!! 선택약정 기준 & 더블스토리지 512G 적용 (KT는 9만 요금제&무부가)
B10: 갤럭시 S26_256G | D10: =IF(COUNTIFS(SKT모델명,$B10,SKT요금제,$D$6)=1, SUMIFS(SKT번이구매가,SKT모델명,$B10,SKT요금제,$D$6)," ") -> 22 | E10: =IF(COUNTIFS(SKT모델명,$B10,SKT요금제,$D$6)=1, SUMIFS(SKT기변구매가,SKT모델명,$B10,SKT요금제,$D$6)," ") -> 30 | F10: =IF(COUNTIFS(KT모델명,$B10,KT요금제,$F$6)=1, SUMIFS(KT번이구매가,KT모델명,$B10,KT요금제,$F$6)," ") -> 12 | G10: =IF(COUNTIFS(KT모델명,$B10,KT요금제,$F$6)=1, SUMIFS(KT기변구매가,KT모델명,$B10,KT요금제,$F$6)," ") -> 18 | H10: =IF(COUNTIFS(LG모델명,$B10,LG요금제,$H$6)=1, SUMIFS(LG번이구매가,LG모델명,$B10,LG요금제,$H$6)," ") -> -6 | I10: =IF(COUNTIFS(LG모델명,$B10,LG요금제,$H$6)=1, SUMIFS(LG기변구매가,LG모델명,$B10,LG요금제,$H$6)," ") -> 7 | M10: =$B10 -> 갤럭시 S26_256G | P10: o | R10: o | T10: O
B11: 갤럭시 S26 플러스_256G | D11: =IF(COUNTIFS(SKT모델명,$B11,SKT요금제,$D$6)=1, SUMIFS(SKT번이구매가,SKT모델명,$B11,SKT요금제,$D$6)," ") -> 42 | E11: =IF(COUNTIFS(SKT모델명,$B11,SKT요금제,$D$6)=1, SUMIFS(SKT기변구매가,SKT모델명,$B11,SKT요금제,$D$6)," ") -> 50 | F11: =IF(COUNTIFS(KT모델명,$B11,KT요금제,$F$6)=1, SUMIFS(KT번이구매가,KT모델명,$B11,KT요금제,$F$6)," ") -> 32 | G11: =IF(COUNTIFS(KT모델명,$B11,KT요금제,$F$6)=1, SUMIFS(KT기변구매가,KT모델명,$B11,KT요금제,$F$6)," ") -> 38 | H11: =IF(COUNTIFS(LG모델명,$B11,LG요금제,$H$6)=1, SUMIFS(LG번이구매가,LG모델명,$B11,LG요금제,$H$6)," ") -> 13 | I11: =IF(COUNTIFS(LG모델명,$B11,LG요금제,$H$6)=1, SUMIFS(LG기변구매가,LG모델명,$B11,LG요금제,$H$6)," ") -> 27 | M11: =$B11 -> 갤럭시 S26 플러스_256G | P11: o | R11: o | T11: O
B12: 갤럭시 S26 울트라_256G | D12: =IF(COUNTIFS(SKT모델명,$B12,SKT요금제,$D$6)=1, SUMIFS(SKT번이구매가,SKT모델명,$B12,SKT요금제,$D$6)," ") -> 76 | E12: =IF(COUNTIFS(SKT모델명,$B12,SKT요금제,$D$6)=1, SUMIFS(SKT기변구매가,SKT모델명,$B12,SKT요금제,$D$6)," ") -> 84 | F12: =IF(COUNTIFS(KT모델명,$B12,KT요금제,$F$6)=1, SUMIFS(KT번이구매가,KT모델명,$B12,KT요금제,$F$6)," ") -> 67 | G12: =IF(COUNTIFS(KT모델명,$B12,KT요금제,$F$6)=1, SUMIFS(KT기변구매가,KT모델명,$B12,KT요금제,$F$6)," ") -> 72 | H12: =IF(COUNTIFS(LG모델명,$B12,LG요금제,$H$6)=1, SUMIFS(LG번이구매가,LG모델명,$B12,LG요금제,$H$6)," ") -> 47 | I12: =IF(COUNTIFS(LG모델명,$B12,LG요금제,$H$6)=1, SUMIFS(LG기변구매가,LG모델명,$B12,LG요금제,$H$6)," ") -> 62 | M12: =$B12 -> 갤럭시 S26 울트라_256G | P12: o | R12: o | T12: O
B13: 갤럭시 S26_512G | D13: =IF(COUNTIFS(SKT모델명,$B13,SKT요금제,$D$6)=1, SUMIFS(SKT번이구매가,SKT모델명,$B13,SKT요금제,$D$6)," ") -> 47 | E13: =IF(COUNTIFS(SKT모델명,$B13,SKT요금제,$D$6)=1, SUMIFS(SKT기변구매가,SKT모델명,$B13,SKT요금제,$D$6)," ") -> 54 | F13: =IF(COUNTIFS(KT모델명,$B13,KT요금제,$F$6)=1, SUMIFS(KT번이구매가,KT모델명,$B13,KT요금제,$F$6)," ") -> 38 | G13: =IF(COUNTIFS(KT모델명,$B13,KT요금제,$F$6)=1, SUMIFS(KT기변구매가,KT모델명,$B13,KT요금제,$F$6)," ") -> 49 | H13: =IF(COUNTIFS(LG모델명,$B13,LG요금제,$H$6)=1, SUMIFS(LG번이구매가,LG모델명,$B13,LG요금제,$H$6)," ") -> 18 | I13: =IF(COUNTIFS(LG모델명,$B13,LG요금제,$H$6)=1, SUMIFS(LG기변구매가,LG모델명,$B13,LG요금제,$H$6)," ") -> 67 | M13: =$B13 -> 갤럭시 S26_512G | R13: o | T13: O
B14: 갤럭시 S26 플러스_512G | D14: =IF(COUNTIFS(SKT모델명,$B14,SKT요금제,$D$6)=1, SUMIFS(SKT번이구매가,SKT모델명,$B14,SKT요금제,$D$6)," ") -> 67 | E14: =IF(COUNTIFS(SKT모델명,$B14,SKT요금제,$D$6)=1, SUMIFS(SKT기변구매가,SKT모델명,$B14,SKT요금제,$D$6)," ") -> 65 | F14: =IF(COUNTIFS(KT모델명,$B14,KT요금제,$F$6)=1, SUMIFS(KT번이구매가,KT모델명,$B14,KT요금제,$F$6)," ") -> 57 | G14: =IF(COUNTIFS(KT모델명,$B14,KT요금제,$F$6)=1, SUMIFS(KT기변구매가,KT모델명,$B14,KT요금제,$F$6)," ") -> 68 | H14: =IF(COUNTIFS(LG모델명,$B14,LG요금제,$H$6)=1, SUMIFS(LG번이구매가,LG모델명,$B14,LG요금제,$H$6)," ") -> 38 | I14: =IF(COUNTIFS(LG모델명,$B14,LG요금제,$H$6)=1, SUMIFS(LG기변구매가,LG모델명,$B14,LG요금제,$H$6)," ") -> 58 | M14: =$B14 -> 갤럭시 S26 플러스_512G | P14: o | R14: o | T14: O
B15: 갤럭시 S26 울트라_512G | D15: =IF(COUNTIFS(SKT모델명,$B15,SKT요금제,$D$6)=1, SUMIFS(SKT번이구매가,SKT모델명,$B15,SKT요금제,$D$6)," ") -> 102 | E15: =IF(COUNTIFS(SKT모델명,$B15,SKT요금제,$D$6)=1, SUMIFS(SKT기변구매가,SKT모델명,$B15,SKT요금제,$D$6)," ") -> 114 | F15: =IF(COUNTIFS(KT모델명,$B15,KT요금제,$F$6)=1, SUMIFS(KT번이구매가,KT모델명,$B15,KT요금제,$F$6)," ") -> 92 | G15: =IF(COUNTIFS(KT모델명,$B15,KT요금제,$F$6)=1, SUMIFS(KT기변구매가,KT모델명,$B15,KT요금제,$F$6)," ") -> 104 | H15: =IF(COUNTIFS(LG모델명,$B15,LG요금제,$H$6)=1, SUMIFS(LG번이구매가,LG모델명,$B15,LG요금제,$H$6)," ") -> 73 | I15: =IF(COUNTIFS(LG모델명,$B15,LG요금제,$H$6)=1, SUMIFS(LG기변구매가,LG모델명,$B15,LG요금제,$H$6)," ") -> 93 | M15: =$B15 -> 갤럭시 S26 울트라_512G | P15: o | R15: o | T15: O
C16: 폰스팟 특가 | D16: 5GX 프리미엄 | F16: 5G 초이스 스페셜 | H16: 플러스 플랜115 | M16: =$B16 -> 0
B17: 11만 요금제~ | D17: 번이 | E17: 기변 | F17: 번이 | G17: 기변 | H17: 번이 | I17: 기변
B18: 삼성 갤럭시 | M18: 삼성 갤럭시
B19: 갤럭시Z플립7 | D19: =IF(COUNTIFS(SKT모델명,$B19,SKT요금제,$D$16)=1, SUMIFS(SKT번이구매가,SKT모델명,$B19,SKT요금제,$D$6)," ") -> 42 | E19: =IF(COUNTIFS(SKT모델명,$B19,SKT요금제,$D$16)=1, SUMIFS(SKT기변구매가,SKT모델명,$B19,SKT요금제,$D$16)," ") -> 77 | F19: =IF(COUNTIFS(KT모델명,$B19,KT요금제,$F$16)=1, SUMIFS(KT번이구매가,KT모델명,$B19,KT요금제,$F$16)," ") -> 33 | G19: =IF(COUNTIFS(KT모델명,$B19,KT요금제,$F$16)=1, SUMIFS(KT기변구매가,KT모델명,$B19,KT요금제,$F$16)," ") -> 55 | H19: =IF(COUNTIFS(LG모델명,$B19,LG요금제,$H$16)=1, SUMIFS(LG번이구매가,LG모델명,$B19,LG요금제,$H$16)," ") -> 52 | I19: =IF(COUNTIFS(LG모델명,$B19,LG요금제,$H$16)=1, SUMIFS(LG기변구매가,LG모델명,$B19,LG요금제,$H$16)," ") -> 64 | M19: =$B19 -> 갤럭시Z플립7 | R19: O | S19: o | T19: O
B20: 갤럭시Z폴드7 | D20: =IF(COUNTIFS(SKT모델명,$B20,SKT요금제,$D$16)=1, SUMIFS(SKT번이구매가,SKT모델명,$B20,SKT요금제,$D$6)," ") -> 135 | E20: =IF(COUNTIFS(SKT모델명,$B20,SKT요금제,$D$16)=1, SUMIFS(SKT기변구매가,SKT모델명,$B20,SKT요금제,$D$6)," ") -> 164 | F20: =IF(COUNTIFS(KT모델명,$B20,KT요금제,$F$16)=1, SUMIFS(KT번이구매가,KT모델명,$B20,KT요금제,$F$16)," ") -> 128 | G20: =IF(COUNTIFS(KT모델명,$B20,KT요금제,$F$16)=1, SUMIFS(KT기변구매가,KT모델명,$B20,KT요금제,$F$16)," ") -> 142 | H20: =IF(COUNTIFS(LG모델명,$B20,LG요금제,$H$16)=1, SUMIFS(LG번이구매가,LG모델명,$B20,LG요금제,$H$16)," ") -> 134 | I20: =IF(COUNTIFS(LG모델명,$B20,LG요금제,$H$16)=1, SUMIFS(LG기변구매가,LG모델명,$B20,LG요금제,$H$16)," ") -> 128 | M20: =$B20 -> 갤럭시Z폴드7 | R20: o | S20: o | T20: o
B21: 갤럭시S25 | D21: =IF(COUNTIFS(SKT모델명,$B21,SKT요금제,$D$16)=1, SUMIFS(SKT번이구매가,SKT모델명,$B21,SKT요금제,$D$6)," ") -> 11 | E21: =IF(COUNTIFS(SKT모델명,$B21,SKT요금제,$D$16)=1, SUMIFS(SKT기변구매가,SKT모델명,$B21,SKT요금제,$D$6)," ") -> 47 | F21: =IF(COUNTIFS(KT모델명,$B21,KT요금제,$F$16)=1, SUMIFS(KT번이구매가,KT모델명,$B21,KT요금제,$F$16)," ") -> -2 | G21: =IF(COUNTIFS(KT모델명,$B21,KT요금제,$F$16)=1, SUMIFS(KT기변구매가,KT모델명,$B21,KT요금제,$F$16)," ") -> -1 | H21: =IF(COUNTIFS(LG모델명,$B21,LG요금제,$H$16)=1, SUMIFS(LG번이구매가,LG모델명,$B21,LG요금제,$H$16)," ") -> 17 | I21: =IF(COUNTIFS(LG모델명,$B21,LG요금제,$H$16)=1, SUMIFS(LG기변구매가,LG모델명,$B21,LG요금제,$H$16)," ") -> 25 | M21: =$B21 -> 갤럭시S25 | P21: o | T21: O
B22: 갤럭시S25+ | D22: =IF(COUNTIFS(SKT모델명,$B22,SKT요금제,$D$16)=1, SUMIFS(SKT번이구매가,SKT모델명,$B22,SKT요금제,$D$6)," ") -> 31 | E22: =IF(COUNTIFS(SKT모델명,$B22,SKT요금제,$D$16)=1, SUMIFS(SKT기변구매가,SKT모델명,$B22,SKT요금제,$D$6)," ") -> 70 | F22: =IF(COUNTIFS(KT모델명,$B22,KT요금제,$F$16)=1, SUMIFS(KT번이구매가,KT모델명,$B22,KT요금제,$F$16)," ") -> 18 | G22: =IF(COUNTIFS(KT모델명,$B22,KT요금제,$F$16)=1, SUMIFS(KT기변구매가,KT모델명,$B22,KT요금제,$F$16)," ") -> 19 | H22: =IF(COUNTIFS(LG모델명,$B22,LG요금제,$H$16)=1, SUMIFS(LG번이구매가,LG모델명,$B22,LG요금제,$H$16)," ") -> 39 | I22: =IF(COUNTIFS(LG모델명,$B22,LG요금제,$H$16)=1, SUMIFS(LG기변구매가,LG모델명,$B22,LG요금제,$H$16)," ") -> 51 | M22: =$B22 -> 갤럭시S25+ | P22: o
B23: 갤럭시S25울트라 | D23: =IF(COUNTIFS(SKT모델명,$B23,SKT요금제,$D$16)=1, SUMIFS(SKT번이구매가,SKT모델명,$B23,SKT요금제,$D$6)," ") -> 65 | E23: =IF(COUNTIFS(SKT모델명,$B23,SKT요금제,$D$16)=1, SUMIFS(SKT기변구매가,SKT모델명,$B23,SKT요금제,$D$6)," ") -> 101 | F23: =IF(COUNTIFS(KT모델명,$B23,KT요금제,$F$16)=1, SUMIFS(KT번이구매가,KT모델명,$B23,KT요금제,$F$16)," ") -> 53 | G23: =IF(COUNTIFS(KT모델명,$B23,KT요금제,$F$16)=1, SUMIFS(KT기변구매가,KT모델명,$B23,KT요금제,$F$16)," ") -> 54 | H23: =IF(COUNTIFS(LG모델명,$B23,LG요금제,$H$16)=1, SUMIFS(LG번이구매가,LG모델명,$B23,LG요금제,$H$16)," ") -> 72 | I23: =IF(COUNTIFS(LG모델명,$B23,LG요금제,$H$16)=1, SUMIFS(LG기변구매가,LG모델명,$B23,LG요금제,$H$16)," ") -> 80 | M23: =$B23 -> 갤럭시S25울트라 | P23: o | T23: O
B24: 갤럭시S25엣지 | D24: =IF(COUNTIFS(SKT모델명,$B24,SKT요금제,$D$16)=1, SUMIFS(SKT번이구매가,SKT모델명,$B24,SKT요금제,$D$6)," ") -> 22 | E24: =IF(COUNTIFS(SKT모델명,$B24,SKT요금제,$D$16)=1, SUMIFS(SKT기변구매가,SKT모델명,$B24,SKT요금제,$D$6)," ") -> 29 | F24: =IF(COUNTIFS(KT모델명,$B24,KT요금제,$F$16)=1, SUMIFS(KT번이구매가,KT모델명,$B24,KT요금제,$F$16)," ") -> 18 | G24: =IF(COUNTIFS(KT모델명,$B24,KT요금제,$F$16)=1, SUMIFS(KT기변구매가,KT모델명,$B24,KT요금제,$F$16)," ") -> 16 | H24: =IF(COUNTIFS(LG모델명,$B24,LG요금제,$H$16)=1, SUMIFS(LG번이구매가,LG모델명,$B24,LG요금제,$H$16)," ") -> 19 | I24: =IF(COUNTIFS(LG모델명,$B24,LG요금제,$H$16)=1, SUMIFS(LG기변구매가,LG모델명,$B24,LG요금제,$H$16)," ") -> 20 | M24: =$B24 -> 갤럭시S25엣지 | P24: 0 | R24: o | S24: o | T24: d
B25: 갤럭시S24+ | D25: =IF(COUNTIFS(SKT모델명,$B25,SKT요금제,$D$16)=1, SUMIFS(SKT번이구매가,SKT모델명,$B25,SKT요금제,$D$6)," ") | E25: =IF(COUNTIFS(SKT모델명,$B25,SKT요금제,$D$16)=1, SUMIFS(SKT기변구매가,SKT모델명,$B25,SKT요금제,$D$6)," ") | F25: =IF(COUNTIFS(KT모델명,$B25,KT요금제,$F$16)=1, SUMIFS(KT번이구매가,KT모델명,$B25,KT요금제,$F$16)," ") | G25: =IF(COUNTIFS(KT모델명,$B25,KT요금제,$F$16)=1, SUMIFS(KT기변구매가,KT모델명,$B25,KT요금제,$F$16)," ") | H25: =IF(COUNTIFS(LG모델명,$B25,LG요금제,$H$16)=1, SUMIFS(LG번이구매가,LG모델명,$B25,LG요금제,$H$16)," ") | I25: =IF(COUNTIFS(LG모델명,$B25,LG요금제,$H$16)=1, SUMIFS(LG기변구매가,LG모델명,$B25,LG요금제,$H$16)," ") | M25: =$B25 -> 갤럭시S24+ | P25: d
B26: 갤럭시S24울트라 | D26: =IF(COUNTIFS(SKT모델명,$B26,SKT요금제,$D$16)=1, SUMIFS(SKT번이구매가,SKT모델명,$B26,SKT요금제,$D$6)," ") | E26: =IF(COUNTIFS(SKT모델명,$B26,SKT요금제,$D$16)=1, SUMIFS(SKT기변구매가,SKT모델명,$B26,SKT요금제,$D$6)," ") | F26: =IF(COUNTIFS(KT모델명,$B26,KT요금제,$F$16)=1, SUMIFS(KT번이구매가,KT모델명,$B26,KT요금제,$F$16)," ") | G26: =IF(COUNTIFS(KT모델명,$B26,KT요금제,$F$16)=1, SUMIFS(KT기변구매가,KT모델명,$B26,KT요금제,$F$16)," ") | H26: =IF(COUNTIFS(LG모델명,$B26,LG요금제,$H$16)=1, SUMIFS(LG번이구매가,LG모델명,$B26,LG요금제,$H$16)," ") | I26: =IF(COUNTIFS(LG모델명,$B26,LG요금제,$H$16)=1, SUMIFS(LG기변구매가,LG모델명,$B26,LG요금제,$H$16)," ") | M26: =$B26 -> 갤럭시S24울트라
B27: 갤럭시S25FE | D27: =IF(COUNTIFS(SKT모델명,$B27,SKT요금제,$D$16)=1, SUMIFS(SKT번이구매가,SKT모델명,$B27,SKT요금제,$D$6)," ") -> -19 | E27: =IF(COUNTIFS(SKT모델명,$B27,SKT요금제,$D$16)=1, SUMIFS(SKT기변구매가,SKT모델명,$B27,SKT요금제,$D$6)," ") -> 1 | F27: =IF(COUNTIFS(KT모델명,$B27,KT요금제,$F$16)=1, SUMIFS(KT번이구매가,KT모델명,$B27,KT요금제,$F$16)," ") | G27: =IF(COUNTIFS(KT모델명,$B27,KT요금제,$F$16)=1, SUMIFS(KT기변구매가,KT모델명,$B27,KT요금제,$F$16)," ") | H27: =IF(COUNTIFS(LG모델명,$B27,LG요금제,$H$16)=1, SUMIFS(LG번이구매가,LG모델명,$B27,LG요금제,$H$16)," ") -> -24 | I27: =IF(COUNTIFS(LG모델명,$B27,LG요금제,$H$16)=1, SUMIFS(LG기변구매가,LG모델명,$B27,LG요금제,$H$16)," ") -> 10 | M27: =$B27 -> 갤럭시S25FE | S27: o
B28: 갤럭시퀀텀6 | D28: =IF(COUNTIFS(SKT모델명,$B28,SKT요금제,$D$16)=1, SUMIFS(SKT번이구매가,SKT모델명,$B28,SKT요금제,$D$6)," ") -> -18 | E28: =IF(COUNTIFS(SKT모델명,$B28,SKT요금제,$D$16)=1, SUMIFS(SKT기변구매가,SKT모델명,$B28,SKT요금제,$D$6)," ") -> -15 | F28: =IF(COUNTIFS(KT모델명,$B28,KT요금제,$F$6)=1, SUMIFS(KT번이구매가,KT모델명,$B28,KT요금제,$F$6)," ") | G28: =IF(COUNTIFS(KT모델명,$B28,KT요금제,$F$6)=1, SUMIFS(KT기변구매가,KT모델명,$B28,KT요금제,$F$6)," ") | H28: =IF(COUNTIFS(LG모델명,$B28,LG요금제,$H$16)=1, SUMIFS(LG번이구매가,LG모델명,$B28,LG요금제,$H$16)," ") | I28: =IF(COUNTIFS(LG모델명,$B28,LG요금제,$H$16)=1, SUMIFS(LG기변구매가,LG모델명,$B28,LG요금제,$H$16)," ") | M28: =$B28 -> 갤럭시퀀텀6
B29: 갤럭시 Z 폴드6 | D29: =IF(COUNTIFS(SKT모델명,$B29,SKT요금제,$D$6)=1, SUMIFS(SKT번이구매가,SKT모델명,$B29,SKT요금제,$D$6)," ") | E29: =IF(COUNTIFS(SKT모델명,$B29,SKT요금제,$D$6)=1, SUMIFS(SKT기변구매가,SKT모델명,$B29,SKT요금제,$D$6)," ") | F29: =IF(COUNTIFS(KT모델명,$B29,KT요금제,$F$6)=1, SUMIFS(KT번이구매가,KT모델명,$B29,KT요금제,$F$6)," ") | G29: =IF(COUNTIFS(KT모델명,$B29,KT요금제,$F$6)=1, SUMIFS(KT기변구매가,KT모델명,$B29,KT요금제,$F$6)," ") | H29: =IF(COUNTIFS(LG모델명,$B29,LG요금제,$H$6)=1, SUMIFS(LG번이구매가,LG모델명,$B29,LG요금제,$H$6)," ") | I29: =IF(COUNTIFS(LG모델명,$B29,LG요금제,$H$6)=1, SUMIFS(LG기변구매가,LG모델명,$B29,LG요금제,$H$6)," ") | M29: =$B29 -> 갤럭시 Z 폴드6
D30: =IF(COUNTIFS(SKT모델명,$B30,SKT요금제,$D$6)=1, SUMIFS(SKT번이구매가,SKT모델명,$B30,SKT요금제,$D$6)," ") | E30: =IF(COUNTIFS(SKT모델명,$B30,SKT요금제,$D$6)=1, SUMIFS(SKT기변구매가,SKT모델명,$B30,SKT요금제,$D$6)," ") | F30: =IF(COUNTIFS(KT모델명,$B30,KT요금제,$F$6)=1, SUMIFS(KT번이구매가,KT모델명,$B30,KT요금제,$F$6)," ") | G30: =IF(COUNTIFS(KT모델명,$B30,KT요금제,$F$6)=1, SUMIFS(KT기변구매가,KT모델명,$B30,KT요금제,$F$6)," ") | H30: =IF(COUNTIFS(LG모델명,$B30,LG요금제,$H$6)=1, SUMIFS(LG번이구매가,LG모델명,$B30,LG요금제,$H$6)," ") | I30: =IF(COUNTIFS(LG모델명,$B30,LG요금제,$H$6)=1, SUMIFS(LG기변구매가,LG모델명,$B30,LG요금제,$H$6)," ") | M30: =$B30 -> 0
D31: =IF(COUNTIFS(SKT모델명,$B31,SKT요금제,$D$6)=1, SUMIFS(SKT번이구매가,SKT모델명,$B31,SKT요금제,$D$6)," ") | E31: =IF(COUNTIFS(SKT모델명,$B31,SKT요금제,$D$6)=1, SUMIFS(SKT기변구매가,SKT모델명,$B31,SKT요금제,$D$6)," ") | F31: =IF(COUNTIFS(KT모델명,$B31,KT요금제,$F$6)=1, SUMIFS(KT번이구매가,KT모델명,$B31,KT요금제,$F$6)," ") | G31: =IF(COUNTIFS(KT모델명,$B31,KT요금제,$F$6)=1, SUMIFS(KT기변구매가,KT모델명,$B31,KT요금제,$F$6)," ") | H31: =IF(COUNTIFS(LG모델명,$B31,LG요금제,$H$6)=1, SUMIFS(LG번이구매가,LG모델명,$B31,LG요금제,$H$6)," ") | I31: =IF(COUNTIFS(LG모델명,$B31,LG요금제,$H$6)=1, SUMIFS(LG기변구매가,LG모델명,$B31,LG요금제,$H$6)," ") | M31: =$B31 -> 0
D32: =IF(COUNTIFS(SKT모델명,$B32,SKT요금제,$D$6)=1, SUMIFS(SKT번이구매가,SKT모델명,$B32,SKT요금제,$D$6)," ") | E32: =IF(COUNTIFS(SKT모델명,$B32,SKT요금제,$D$6)=1, SUMIFS(SKT기변구매가,SKT모델명,$B32,SKT요금제,$D$6)," ") | F32: =IF(COUNTIFS(KT모델명,$B32,KT요금제,$F$6)=1, SUMIFS(KT번이구매가,KT모델명,$B32,KT요금제,$F$6)," ") | G32: =IF(COUNTIFS(KT모델명,$B32,KT요금제,$F$6)=1, SUMIFS(KT기변구매가,KT모델명,$B32,KT요금제,$F$6)," ") | H32: =IF(COUNTIFS(LG모델명,$B32,LG요금제,$H$6)=1, SUMIFS(LG번이구매가,LG모델명,$B32,LG요금제,$H$6)," ") | I32: =IF(COUNTIFS(LG모델명,$B32,LG요금제,$H$6)=1, SUMIFS(LG기변구매가,LG모델명,$B32,LG요금제,$H$6)," ") | M32: =$B32 -> 0
D33: =IF(COUNTIFS(SKT모델명,$B33,SKT요금제,$D$6)=1, SUMIFS(SKT번이구매가,SKT모델명,$B33,SKT요금제,$D$6)," ") | E33: =IF(COUNTIFS(SKT모델명,$B33,SKT요금제,$D$6)=1, SUMIFS(SKT기변구매가,SKT모델명,$B33,SKT요금제,$D$6)," ") | F33: =IF(COUNTIFS(KT모델명,$B33,KT요금제,$F$6)=1, SUMIFS(KT번이구매가,KT모델명,$B33,KT요금제,$F$6)," ") | G33: =IF(COUNTIFS(KT모델명,$B33,KT요금제,$F$6)=1, SUMIFS(KT기변구매가,KT모델명,$B33,KT요금제,$F$6)," ") | H33: =IF(COUNTIFS(LG모델명,$B33,LG요금제,$H$6)=1, SUMIFS(LG번이구매가,LG모델명,$B33,LG요금제,$H$6)," ") | I33: =IF(COUNTIFS(LG모델명,$B33,LG요금제,$H$6)=1, SUMIFS(LG기변구매가,LG모델명,$B33,LG요금제,$H$6)," ") | M33: =$B33 -> 0
D34: =IF(COUNTIFS(SKT모델명,$B34,SKT요금제,$D$6)=1, SUMIFS(SKT번이구매가,SKT모델명,$B34,SKT요금제,$D$6)," ") | E34: =IF(COUNTIFS(SKT모델명,$B34,SKT요금제,$D$6)=1, SUMIFS(SKT기변구매가,SKT모델명,$B34,SKT요금제,$D$6)," ") | F34: =IF(COUNTIFS(KT모델명,$B34,KT요금제,$F$6)=1, SUMIFS(KT번이구매가,KT모델명,$B34,KT요금제,$F$6)," ") | G34: =IF(COUNTIFS(KT모델명,$B34,KT요금제,$F$6)=1, SUMIFS(KT기변구매가,KT모델명,$B34,KT요금제,$F$6)," ") | H34: =IF(COUNTIFS(LG모델명,$B34,LG요금제,$H$6)=1, SUMIFS(LG번이구매가,LG모델명,$B34,LG요금제,$H$6)," ") | I34: =IF(COUNTIFS(LG모델명,$B34,LG요금제,$H$6)=1, SUMIFS(LG기변구매가,LG모델명,$B34,LG요금제,$H$6)," ") | M34: =$B34 -> 0
D35: =IF(COUNTIFS(SKT모델명,$B35,SKT요금제,$D$6)=1, SUMIFS(SKT번이구매가,SKT모델명,$B35,SKT요금제,$D$6)," ") | E35: =IF(COUNTIFS(SKT모델명,$B35,SKT요금제,$D$6)=1, SUMIFS(SKT기변구매가,SKT모델명,$B35,SKT요금제,$D$6)," ") | F35: =IF(COUNTIFS(KT모델명,$B35,KT요금제,$F$6)=1, SUMIFS(KT번이구매가,KT모델명,$B35,KT요금제,$F$6)," ") | G35: =IF(COUNTIFS(KT모델명,$B35,KT요금제,$F$6)=1, SUMIFS(KT기변구매가,KT모델명,$B35,KT요금제,$F$6)," ") | H35: =IF(COUNTIFS(LG모델명,$B35,LG요금제,$H$6)=1, SUMIFS(LG번이구매가,LG모델명,$B35,LG요금제,$H$6)," ") | I35: =IF(COUNTIFS(LG모델명,$B35,LG요금제,$H$6)=1, SUMIFS(LG기변구매가,LG모델명,$B35,LG요금제,$H$6)," ") | M35: =$B35 -> 0
D36: =IF(COUNTIFS(SKT모델명,$B36,SKT요금제,$D$6)=1, SUMIFS(SKT번이구매가,SKT모델명,$B36,SKT요금제,$D$6)," ") | E36: =IF(COUNTIFS(SKT모델명,$B36,SKT요금제,$D$6)=1, SUMIFS(SKT기변구매가,SKT모델명,$B36,SKT요금제,$D$6)," ") | F36: =IF(COUNTIFS(KT모델명,$B36,KT요금제,$F$6)=1, SUMIFS(KT번이구매가,KT모델명,$B36,KT요금제,$F$6)," ") | G36: =IF(COUNTIFS(KT모델명,$B36,KT요금제,$F$6)=1, SUMIFS(KT기변구매가,KT모델명,$B36,KT요금제,$F$6)," ") | H36: =IF(COUNTIFS(LG모델명,$B36,LG요금제,$H$6)=1, SUMIFS(LG번이구매가,LG모델명,$B36,LG요금제,$H$6)," ") | I36: =IF(COUNTIFS(LG모델명,$B36,LG요금제,$H$6)=1, SUMIFS(LG기변구매가,LG모델명,$B36,LG요금제,$H$6)," ") | M36: =$B36 -> 0
D37: =IF(COUNTIFS(SKT모델명,$B37,SKT요금제,$D$6)=1, SUMIFS(SKT번이구매가,SKT모델명,$B37,SKT요금제,$D$6)," ") | E37: =IF(COUNTIFS(SKT모델명,$B37,SKT요금제,$D$6)=1, SUMIFS(SKT기변구매가,SKT모델명,$B37,SKT요금제,$D$6)," ") | F37: =IF(COUNTIFS(KT모델명,$B37,KT요금제,$F$6)=1, SUMIFS(KT번이구매가,KT모델명,$B37,KT요금제,$F$6)," ") | G37: =IF(COUNTIFS(KT모델명,$B37,KT요금제,$F$6)=1, SUMIFS(KT기변구매가,KT모델명,$B37,KT요금제,$F$6)," ") | H37: =IF(COUNTIFS(LG모델명,$B37,LG요금제,$H$6)=1, SUMIFS(LG번이구매가,LG모델명,$B37,LG요금제,$H$6)," ") | I37: =IF(COUNTIFS(LG모델명,$B37,LG요금제,$H$6)=1, SUMIFS(LG기변구매가,LG모델명,$B37,LG요금제,$H$6)," ") | M37: =$B37 -> 0
B38: 애플 아이폰 | M38: 애플 아이폰
B39: 아이폰17_256G | D39: =IF(COUNTIFS(SKT모델명,$B39,SKT요금제,$D$16)=1, SUMIFS(SKT번이구매가,SKT모델명,$B39,SKT요금제,$D$16)," ") -> 40 | E39: =IF(COUNTIFS(SKT모델명,$B39,SKT요금제,$D$16)=1, SUMIFS(SKT기변구매가,SKT모델명,$B39,SKT요금제,$D$16)," ") -> 64 | F39: =IF(COUNTIFS(KT모델명,$B39,KT요금제,$F$16)=1, SUMIFS(KT번이구매가,KT모델명,$B39,KT요금제,$F$16)," ") -> 15 | G39: =IF(COUNTIFS(KT모델명,$B39,KT요금제,$F$16)=1, SUMIFS(KT기변구매가,KT모델명,$B39,KT요금제,$F$16)," ") -> 37 | H39: =IF(COUNTIFS(LG모델명,$B39,LG요금제,$H$16)=1, SUMIFS(LG번이구매가,LG모델명,$B39,LG요금제,$H$16)," ") -> 11 | I39: =IF(COUNTIFS(LG모델명,$B39,LG요금제,$H$16)=1, SUMIFS(LG기변구매가,LG모델명,$B39,LG요금제,$H$16)," ") -> 50 | M39: =$B39 -> 아이폰17_256G | P39: o | T39: O
B40: 아이폰17_512G | D40: =IF(COUNTIFS(SKT모델명,$B40,SKT요금제,$D$16)=1, SUMIFS(SKT번이구매가,SKT모델명,$B40,SKT요금제,$D$16)," ") -> 70 | E40: =IF(COUNTIFS(SKT모델명,$B40,SKT요금제,$D$16)=1, SUMIFS(SKT기변구매가,SKT모델명,$B40,SKT요금제,$D$16)," ") -> 94 | F40: =IF(COUNTIFS(KT모델명,$B40,KT요금제,$F$16)=1, SUMIFS(KT번이구매가,KT모델명,$B40,KT요금제,$F$16)," ") -> 44 | G40: =IF(COUNTIFS(KT모델명,$B40,KT요금제,$F$16)=1, SUMIFS(KT기변구매가,KT모델명,$B40,KT요금제,$F$16)," ") -> 66 | H40: =IF(COUNTIFS(LG모델명,$B40,LG요금제,$H$16)=1, SUMIFS(LG번이구매가,LG모델명,$B40,LG요금제,$H$16)," ") -> 42 | I40: =IF(COUNTIFS(LG모델명,$B40,LG요금제,$H$16)=1, SUMIFS(LG기변구매가,LG모델명,$B40,LG요금제,$H$16)," ") -> 79 | M40: =$B40 -> 아이폰17_512G | P40: o | T40: O
B41: 아이폰에어_256G | D41: =IF(COUNTIFS(SKT모델명,$B41,SKT요금제,$D$16)=1, SUMIFS(SKT번이구매가,SKT모델명,$B41,SKT요금제,$D$16)," ") -> 65 | E41: =IF(COUNTIFS(SKT모델명,$B41,SKT요금제,$D$16)=1, SUMIFS(SKT기변구매가,SKT모델명,$B41,SKT요금제,$D$16)," ") -> 82 | F41: =IF(COUNTIFS(KT모델명,$B41,KT요금제,$F$16)=1, SUMIFS(KT번이구매가,KT모델명,$B41,KT요금제,$F$16)," ") -> 46 | G41: =IF(COUNTIFS(KT모델명,$B41,KT요금제,$F$16)=1, SUMIFS(KT기변구매가,KT모델명,$B41,KT요금제,$F$16)," ") -> 68 | H41: =IF(COUNTIFS(LG모델명,$B41,LG요금제,$H$16)=1, SUMIFS(LG번이구매가,LG모델명,$B41,LG요금제,$H$16)," ") -> -18 | I41: =IF(COUNTIFS(LG모델명,$B41,LG요금제,$H$16)=1, SUMIFS(LG기변구매가,LG모델명,$B41,LG요금제,$H$16)," ") -> 77 | M41: =$B41 -> 아이폰에어_256G | O41: o | P41: o
B42: 아이폰에어_512G | D42: =IF(COUNTIFS(SKT모델명,$B42,SKT요금제,$D$16)=1, SUMIFS(SKT번이구매가,SKT모델명,$B42,SKT요금제,$D$16)," ") -> 95 | E42: =IF(COUNTIFS(SKT모델명,$B42,SKT요금제,$D$16)=1, SUMIFS(SKT기변구매가,SKT모델명,$B42,SKT요금제,$D$16)," ") -> 112 | F42: =IF(COUNTIFS(KT모델명,$B42,KT요금제,$F$16)=1, SUMIFS(KT번이구매가,KT모델명,$B42,KT요금제,$F$16)," ") -> 76 | G42: =IF(COUNTIFS(KT모델명,$B42,KT요금제,$F$16)=1, SUMIFS(KT기변구매가,KT모델명,$B42,KT요금제,$F$16)," ") -> 98 | H42: =IF(COUNTIFS(LG모델명,$B42,LG요금제,$H$16)=1, SUMIFS(LG번이구매가,LG모델명,$B42,LG요금제,$H$16)," ") -> 10 | I42: =IF(COUNTIFS(LG모델명,$B42,LG요금제,$H$16)=1, SUMIFS(LG기변구매가,LG모델명,$B42,LG요금제,$H$16)," ") -> 107 | M42: =$B42 -> 아이폰에어_512G | O42: o | P42: o
...

Sheet 폰스팟 인터넷 시세표
B2: KT 4월 인터넷 / IPTV 지원금
B3: 가입유형 | C3: 인터넷 + TV | D3: 인터넷 + TV + 번호이동 | F3: 인터넷 + TV + 기기변경 | H3: 예상 청구 금액
B4: 인터넷 에센스 (1G) + IPTV 모든G | C4: 40만원 +10만원(상품권) | D4: 80만원 +10만원(상품권) | F4: 75만원 + 10만원(상품권) | H4: 58850
B5: 인터넷 베이직 (500MB) + IPTV 모든G | C5: 30만원 +7만원(상품권) | D5: 65만원 + 7만원(상품권) | F5: 60만원 + 7만원(상품권) | H5: 54450
B6: 예상 청구금액은 모바일 요금제를 제외한 인터넷 + 티비만 합산된 예상 월 청구 금액이며, 실제 금액은 다를 수 있습니다.
B7: 우리 동네 근처 휴대폰 성지
B9: SKT 5월 인터넷 / IPTV 지원금
B10: 가입유형 | C10: 인터넷+TV+번호이동 | E10: 유선 월 청구금액 | G10: 모바일+인터넷만
B11: 초고속(1G)+tv all | C11: 80만원 | E11: 월 59,400원 | G11: 50만원 | I11: 월 38,500원
B12: 초고속(500MB)+tv all | C12: 70만원 | E12: 월 53,900원 | G12: 40만원 | I12: 월 33,000원
B13: 초고속(100MB)+tv all | C13: 50만원 | E13: 월 42,900원 | G13: 25만원 | I13: 월 22,000원
B14: 우리 동네 근처 휴대폰 성지
B16: LG U+ 5월 인터넷 / IPTV 지원금
B17: 인터넷+TV | C17: 인+티+번호이동 | E17: 인+티+기변 | H17: 월 청구금액
B18: 모바일+ 프리미엄안심보상(1G) +TV(프리미엄VOD) | C18: 80만원 | E18: 75만원 | H18: 월 62,700원
B19: 모바일+ 프리미엄안심(500MB) +TV(프리미엄VOD) | C19: 70만원 | E19: 65만원 | H19: 월 57,200원
B20: 우리 동네 근처 휴대폰 성지
B22: 구매 전 안내사항
B24: ① 월 청구금액은 결합 할인이 제외된 예상 금액으로 결합 유형에 따라 청구 금액이 변동될 수 있습니다. (부가세 포함 금액입니다)
B25: ② 원스톱 전환 서비스를 기준으로 작성되었으며 원스톱 전환 서비스를 이용하지 않을 경우, 금액이 변동될 수 있습니다.
B26: 원스톱 전환 서비스 : 신규 통신사 가입 시, 기존 통신사 서비스 해지를 한번에 처리할 수 있는 제도
B27: ③ 본 시세표는 참고용이며 계약하신 조건에 따라 지원금이 변동될 수 있습니다. TV셋탑, 안심서비스 등 상품 구성에 따라 변경될 수 있음
B28: ④ 인터넷 신규 개통 시, 지원금 축소되오니 참고 부탁드립니다.
B30: 우리 동네 근처 휴대폰 성지

Sheet ADMIN
B2: ■ 어드민에서 구매가 붙여넣을 때, 노란색 색칠된 부분에 붙여넣기 | P2: 쓸 필요 없음
B4: KT ADMIN 구매가 | H4: 수정 절대 금지 | J4: SKT 구매가 | P4: 수정 절대 금지 | R4: LG U+ 구매가 | X4: 수정 절대 금지
B5: 통신사 | C5: 요금제 | D5: 모델명 | E5: 번이 | F5: 기변 | G5: 내방 | H5: 요금제 매칭용 | J5: 통신사 | K5: 요금제 | L5: 모델명 | M5: 번이 | N5: 기변 | O5: 내방 | P5: 요금제 매칭용 | R5: 통신사 | S5: 요금제 | T5: 모델명 | U5: 번이 | V5: 기변 | W5: 내방 | X5: 요금제 매칭용
B6: KT | C6: 5G 초이스 스페셜 (초이스선택가능) | D6: 갤럭시 S26_256G | E6: 12 | F6: 18 | H6: =SUBSTITUTE($C6, " (초이스선택가능)","") -> 5G 초이스 스페셜 | J6: SKT | K6: 5GX 프리미엄 | L6: 갤럭시 S26_256G | M6: 22 | N6: 30 | P6: =SUBSTITUTE($K6, "(초이스선택가능)","") -> 5GX 프리미엄 | R6: LG | S6: (넷플릭스) 플러스 플랜115 | T6: 갤럭시 S26_256G | U6: -6 | V6: 7 | X6: 플러스 플랜115
B7: KT | C7: 5G 초이스 스페셜 (초이스선택가능) | D7: 갤럭시 S26_512G | E7: 38 | F7: 49 | H7: =SUBSTITUTE($C7, " (초이스선택가능)","") -> 5G 초이스 스페셜 | J7: SKT | K7: 5GX 프리미엄 | L7: 갤럭시 S26_512G | M7: 47 | N7: 54 | P7: =SUBSTITUTE($K7, "(초이스선택가능)","") -> 5GX 프리미엄 | R7: LG | S7: (넷플릭스) 플러스 플랜115 | T7: 갤럭시 S26_512G | U7: 18 | V7: 67 | X7: 플러스 플랜115
B8: KT | C8: 5G 초이스 스페셜 (초이스선택가능) | D8: 갤럭시 S26 플러스_256G | E8: 32 | F8: 38 | H8: =SUBSTITUTE($C8, " (초이스선택가능)","") -> 5G 초이스 스페셜 | J8: SKT | K8: 5GX 프리미엄 | L8: 갤럭시 S26 플러스_256G | M8: 42 | N8: 50 | P8: =SUBSTITUTE($K8, "(초이스선택가능)","") -> 5GX 프리미엄 | R8: LG | S8: (넷플릭스) 플러스 플랜115 | T8: 갤럭시 S26 플러스_256G | U8: 13 | V8: 27 | X8: 플러스 플랜115
B9: KT | C9: 5G 초이스 스페셜 (초이스선택가능) | D9: 갤럭시 S26 플러스_512G | E9: 57 | F9: 68 | H9: =SUBSTITUTE($C9, " (초이스선택가능)","") -> 5G 초이스 스페셜 | J9: SKT | K9: 5GX 프리미엄 | L9: 갤럭시 S26 플러스_512G | M9: 67 | N9: 65 | P9: =SUBSTITUTE($K9, "(초이스선택가능)","") -> 5GX 프리미엄 | R9: LG | S9: (넷플릭스) 플러스 플랜115 | T9: 갤럭시 S26 플러스_512G | U9: 38 | V9: 58 | X9: 플러스 플랜115
B10: KT | C10: 5G 초이스 스페셜 (초이스선택가능) | D10: 갤럭시 S26 울트라_256G | E10: 67 | F10: 72 | H10: =SUBSTITUTE($C10, " (초이스선택가능)","") -> 5G 초이스 스페셜 | J10: SKT | K10: 5GX 프리미엄 | L10: 갤럭시 S26 울트라_256G | M10: 76 | N10: 84 | P10: =SUBSTITUTE($K10, "(초이스선택가능)","") -> 5GX 프리미엄 | R10: LG | S10: (넷플릭스) 플러스 플랜115 | T10: 갤럭시 S26 울트라_256G | U10: 47 | V10: 62 | X10: 플러스 플랜115
B11: KT | C11: 5G 초이스 스페셜 (초이스선택가능) | D11: 갤럭시 S26 울트라_512G | E11: 92 | F11: 104 | H11: =SUBSTITUTE($C11, " (초이스선택가능)","") -> 5G 초이스 스페셜 | J11: SKT | K11: 5GX 프리미엄 | L11: 갤럭시 S26 울트라_512G | M11: 102 | N11: 114 | P11: =SUBSTITUTE($K11, "(초이스선택가능)","") -> 5GX 프리미엄 | R11: LG | S11: (넷플릭스) 플러스 플랜115 | T11: 갤럭시 S26 울트라_512G | U11: 73 | V11: 93 | X11: 플러스 플랜115
B12: KT | C12: 5G 초이스 스페셜 (초이스선택가능) | D12: 갤럭시Z플립7 | E12: 33 | F12: 55 | H12: =SUBSTITUTE($C12, " (초이스선택가능)","") -> 5G 초이스 스페셜 | J12: SKT | K12: 5GX 프리미엄 | L12: 갤럭시Z플립7 | M12: 42 | N12: 77 | P12: =SUBSTITUTE($K12, "(초이스선택가능)","") -> 5GX 프리미엄 | R12: LG | S12: (넷플릭스) 플러스 플랜115 | T12: 갤럭시Z플립7 | U12: 52 | V12: 64 | X12: 플러스 플랜115
B13: KT | C13: 5G 초이스 스페셜 (초이스선택가능) | D13: 갤럭시Z폴드7 | E13: 128 | F13: 142 | H13: =SUBSTITUTE($C13, " (초이스선택가능)","") -> 5G 초이스 스페셜 | J13: SKT | K13: 5GX 프리미엄 | L13: 갤럭시Z폴드7 | M13: 135 | N13: 164 | P13: =SUBSTITUTE($K13, "(초이스선택가능)","") -> 5GX 프리미엄 | R13: LG | S13: (넷플릭스) 플러스 플랜115 | T13: 갤럭시Z폴드7 | U13: 134 | V13: 128 | X13: 플러스 플랜115
B14: KT | C14: 5G 초이스 스페셜 (초이스선택가능) | D14: 갤럭시S25엣지 | E14: 18 | F14: 16 | H14: =SUBSTITUTE($C14, " (초이스선택가능)","") -> 5G 초이스 스페셜 | J14: SKT | K14: 5GX 프리미엄 | L14: 갤럭시S25엣지 | M14: 22 | N14: 29 | P14: =SUBSTITUTE($K14, "(초이스선택가능)","") -> 5GX 프리미엄 | R14: LG | S14: (넷플릭스) 플러스 플랜115 | T14: 갤럭시S25엣지 | U14: 19 | V14: 20 | X14: 플러스 플랜115
B15: KT | C15: 5G 초이스 스페셜 (초이스선택가능) | D15: 갤럭시S25엣지(개봉) | E15: 6 | F15: 15 | H15: =SUBSTITUTE($C15, " (초이스선택가능)","") -> 5G 초이스 스페셜 | J15: SKT | K15: 5GX 프리미엄 | L15: 갤럭시S25 | M15: 11 | N15: 47 | P15: =SUBSTITUTE($K15, "(초이스선택가능)","") -> 5GX 프리미엄 | R15: LG | S15: (넷플릭스) 플러스 플랜115 | T15: 갤럭시S25 | U15: 17 | V15: 25 | X15: 플러스 플랜115
B16: KT | C16: 5G 초이스 스페셜 (초이스선택가능) | D16: 갤럭시S25 | E16: -2 | F16: -1 | H16: =SUBSTITUTE($C16, " (초이스선택가능)","") -> 5G 초이스 스페셜 | J16: SKT | K16: 5GX 프리미엄 | L16: 갤럭시S25+ | M16: 31 | N16: 70 | P16: =SUBSTITUTE($K16, "(초이스선택가능)","") -> 5GX 프리미엄 | R16: LG | S16: (넷플릭스) 플러스 플랜115 | T16: 갤럭시S25+ | U16: 39 | V16: 51 | X16: 플러스 플랜115
B17: KT | C17: 5G 초이스 스페셜 (초이스선택가능) | D17: 갤럭시S25(개봉) | E17: -22 | F17: -19 | H17: =SUBSTITUTE($C17, " (초이스선택가능)","") -> 5G 초이스 스페셜 | J17: SKT | K17: 5GX 프리미엄 | L17: 갤럭시S25울트라 | M17: 65 | N17: 101 | P17: =SUBSTITUTE($K17, "(초이스선택가능)","") -> 5GX 프리미엄 | R17: LG | S17: (넷플릭스) 플러스 플랜115 | T17: 갤럭시S25울트라 | U17: 72 | V17: 80 | X17: 플러스 플랜115
... B27: KT | C27: 5G 초이스 스페셜 (초이스선택가능) | D27: 아이폰17_256G | E27: 15 | F27: 37 | H27: =SUBSTITUTE($C27, " (초이스선택가능)","") -> 5G 초이스 스페셜 | J27: SKT | K27: 5GX 프리미엄 | L27: 아이폰17프로맥스_256G | M27: 130 | N27: 174 | P27: =SUBSTITUTE($K27, "(초이스선택가능)","") -> 5GX 프리미엄 | R27: LG | S27: (넷플릭스) 플러스 플랜115 | T27: 아이폰17프로맥스_512G | U27: 146 | V27: 177 | X27: 플러스 플랜115
B28: KT | C28: 5G 초이스 스페셜 (초이스선택가능) | D28: 아이폰17_512G | E28: 44 | F28: 66 | H28: =SUBSTITUTE($C28, " (초이스선택가능)","") -> 5G 초이스 스페셜 | J28: SKT | K28: 5GX 프리미엄 | L28: 아이폰17프로맥스_512G | M28: 161 | N28: 205 | P28: =SUBSTITUTE($K28, "(초이스선택가능)","") -> 5GX 프리미엄 | R28: LG | S28: (넷플릭스) 플러스 플랜115 | T28: 아이폰16_128G | U28: -5 | V28: 45 | X28: 플러스 플랜115 | AA28: 플러스 플랜115
B29: KT | C29: 5G 초이스 스페셜 (초이스선택가능) | D29: 아이폰에어_256G | E29: 46 | F29: 68 | H29: =SUBSTITUTE($C29, " (초이스선택가능)","") -> 5G 초이스 스페셜 | J29: SKT | K29: 5GX 프리미엄 | L29: 아이폰16E_128G | M29: 12 | N29: 41 | P29: =SUBSTITUTE($K29, "(초이스선택가능)","") -> 5GX 프리미엄 | R29: LG | S29: (넷플릭스) 플러스 플랜115 | T29: 아이폰16_256G | U29: 8 | V29: 60 | X29: 플러스 플랜115
B30: KT | C30: 5G 초이스 스페셜 (초이스선택가능) | D30: 아이폰에어_512G | E30: 76 | F30: 98 | H30: =SUBSTITUTE($C30, " (초이스선택가능)","") -> 5G 초이스 스페셜 | J30: SKT | K30: 5GX 프리미엄 | L30: 아이폰16E_256G | M30: 27 | N30: 56 | P30: =SUBSTITUTE($K30, "(초이스선택가능)","") -> 5GX 프리미엄 | R30: LG | S30: (넷플릭스) 플러스 플랜115 | T30: 아이폰16플러스_128G | U30: 30 | V30: 79 | X30: 플러스 플랜115
B31: KT | C31: 5G 초이스 스페셜 (초이스선택가능) | D31: 아이폰17프로_256G | E31: 71 | F31: 88 | H31: =SUBSTITUTE($C31, " (초이스선택가능)","") -> 5G 초이스 스페셜 | J31: SKT | K31: 5GX 프리미엄 | L31: 아이폰16E_512G | M31: 56 | N31: 85 | P31: =SUBSTITUTE($K31, "(초이스선택가능)","") -> 5GX 프리미엄 | R31: LG | S31: (넷플릭스) 플러스 플랜115 | T31: 갤럭시 Z 폴드6(개봉) | U31: 181 | V31: 181 | W31: 내방 | X31: 플러스 플랜115
B32: KT | C32: 5G 초이스 스페셜 (초이스선택가능) | D32: 아이폰17프로_512G | E32: 102 | F32: 119 | H32: =SUBSTITUTE($C32, " (초이스선택가능)","") -> 5G 초이스 스페셜 | J32: SKT | K32: T플랜 세이브 | L32: 갤럭시A17 | M32: -12 | N32: 32 | P32: =SUBSTITUTE($K32, "(초이스선택가능)","") -> T플랜 세이브 | R32: LG | S32: (넷플릭스) 플러스 플랜115 | T32: 아이폰16플러스_256G | U32: 43 | V32: 95 | X32: 플러스 플랜115
B33: KT | C33: 5G 초이스 스페셜 (초이스선택가능) | D33: 아이폰17프로맥스_256G | E33: 116 | F33: 133 | H33: =SUBSTITUTE($C33, " (초이스선택가능)","") -> 5G 초이스 스페셜 | J33: SKT | L33: 갤럭시 S26_256G | M33: 126 | N33: 126 | R33: LG | S33: (넷플릭스) 플러스 플랜115 | T33: 아이폰16프로_128G | U33: 24 | V33: 74 | X33: 플러스 플랜115
B34: KT | C34: 5G 초이스 스페셜 (초이스선택가능) | D34: 아이폰17프로맥스_512G | E34: 147 | F34: 164 | H34: =SUBSTITUTE($C34, " (초이스선택가능)","") -> 5G 초이스 스페셜 | J34: SKT | L34: 갤럭시 S26_512G | M34: 151 | N34: 151 | R34: LG | S34: (넷플릭스) 플러스 플랜115 | T34: 아이폰16프로_256G | U34: 38 | V34: 90 | X34: 플러스 플랜115
B35: KT | C35: 5g 슬림 4GB | D35: 갤럭시 A17 | E35: -6 | F35: 26 | H35: =SUBSTITUTE($C35, " (초이스선택가능)","") -> 5g 슬림 4GB | J35: SKT | L35: 갤럭시 S26 플러스_256G | M35: 146 | N35: 146 | R35: LG | S35: (넷플릭스) 플러스 플랜115 | T35: 아이폰16E_128G | U35: -15 | V35: 23 | X35: 플러스 플랜115
B36: KT | C36: 5G 심플30GB | D36: 갤럭시 A17 | E36: -12 | F36: 22 | H36: =SUBSTITUTE($C36, " (초이스선택가능)","") -> 5G 심플30GB | J36: SKT | L36: 갤럭시 S26 플러스_512G | M36: 171 | N36: 171 | R36: LG | S36: 5G 키즈 29 | T36: 키즈폰 무너2 | U36: 45 | V36: 45 | X36: =SUBSTITUTE(S36,"(넷플릭스)","") -> 5G 키즈 29
B37: KT | C37: Y주니어 19.8 | D37: 폼폼푸린 키즈폰 | E37: 11 | F37: 36 | H37: =SUBSTITUTE($C37, " (초이스선택가능)","") -> Y주니어 19.8 | J37: SKT | L37: 갤럭시 S26 울트라_256G | M37: 180 | N37: 180 | R37: LG | T37: 갤럭시 S26_256G | U37: 126 | V37: 126 | X37: =SUBSTITUTE(S37,"(넷플릭스)","")
B38: KT | C38: 5g 슬림 4GB | D38: 갤럭시점프4 | E38: 4 | F38: 9 | H38: =SUBSTITUTE($C38, " (초이스선택가능)","") -> 5g 슬림 4GB | J38: SKT | L38: 갤럭시 S26 울트라_512G | M38: 206 | N38: 206 | R38: LG | S38: (넷플릭스) 플러스 플랜115 | T38: 갤럭시 S26_256G | U38: -7 | V38: 7 | X38: =SUBSTITUTE(S38,"(넷플릭스)","") -> 플러스 플랜115
B39: KT | C39: 5G 심플30GB | D39: 갤럭시점프4 | E39: -2 | F39: 3 | H39: =SUBSTITUTE($C39, " (초이스선택가능)","") -> 5G 심플30GB | J39: SKT | L39: 갤럭시A17_ZEM포켓피스 | M39: 35 | N39: 35 | R39: LG | S39: (넷플릭스) 플러스 플랜115 | T39: 갤럭시 S26_256G | U39: -7 | V39: 7 | X39: =SUBSTITUTE(S39,"(넷플릭스)","") -> 플러스 플랜115
B40: KT | C40: 5G 초이스 베이직 (초이스선택가능) | D40: 갤럭시Z폴드7(개봉) | E40: 98 | F40: 110 | H40: =SUBSTITUTE($C40, " (초이스선택가능)","") -> 5G 초이스 베이직 | J40: SKT | L40: 갤럭시A17 | M40: 32 | N40: 32 | R40: LG | T40: 갤럭시 S26_512G | U40: 151 | V40: 151 | X40: =SUBSTITUTE(S40,"(넷플릭스)","")
B41: KT | C41: 5G 초이스 베이직 (초이스선택가능) | D41: 갤럭시Z플립7(개봉) | E41: 23 | F41: 35 | H41: =SUBSTITUTE($C41, " (초이스선택가능)","") -> 5G 초이스 베이직 | R41: LG | T41: 갤럭시 S26 플러스_256G | U41: 146 | V41: 146 | X41: =SUBSTITUTE(S41,"(넷플릭스)","")
B42: KT | C42: 5G 초이스 베이직 (초이스선택가능) | D42: 갤럭시 S26_256G | E42: 45 | F42: 59 | H42: =SUBSTITUTE($C42, " (초이스선택가능)","") -> 5G 초이스 베이직 | R42: LG | T42: 갤럭시 S26 플러스_512G | U42: 171 | V42: 171 | X42: =SUBSTITUTE(S42,"(넷플릭스)","")
B43: KT | C43: 5G 초이스 베이직 (초이스선택가능) | D43: 갤럭시 S26_512G | E43: 71 | F43: 85 | H43: =SUBSTITUTE($C43, " (초이스선택가능)","") -> 5G 초이스 베이직 | P43: =SUBSTITUTE($K43, "(초이스선택가능)","") | R43: LG | T43: 갤럭시 S26 울트라_256G | U43: 180 | V43: 180 | X43: =SUBSTITUTE(S43,"(넷플릭스)","")
B44: KT | C44: 5G 초이스 베이직 (초이스선택가능) | D44: 갤럭시 S26 플러스_256G | E44: 65 | F44: 79 | H44: =SUBSTITUTE($C44, " (초이스선택가능)","") -> 5G 초이스 베이직 | P44: =SUBSTITUTE($K44, "(초이스선택가능)","") | R44: LG | T44: 갤럭시 S26 울트라_512G | U44: 206 | V44: 206 | X44: =SUBSTITUTE(S44,"(넷플릭스)","")
B45: KT | C45: 5G 초이스 베이직 (초이스선택가능) | D45: 갤럭시 S26 플러스_512G | E45: 90 | F45: 104 | H45: =SUBSTITUTE($C45, " (초이스선택가능)","") -> 5G 초이스 베이직 | P45: =SUBSTITUTE($K45, "(초이스선택가능)","") | R45: LG | S45: (넷플릭스) 플러스 플랜115 | T45: 아이폰에어_1TB | U45: 40 | V45: 138 | X45: =SUBSTITUTE(S45,"(넷플릭스)","") -> 플러스 플랜115
B46: KT | C46: 5G 초이스 베이직 (초이스선택가능) | D46: 갤럭시 S26 울트라_256G | E46: 100 | F46: 114 | H46: =SUBSTITUTE($C46, " (초이스선택가능)","") -> 5G 초이스 베이직 | P46: =SUBSTITUTE($K46, "(초이스선택가능)","") | R46: LG | T46: 키즈폰 무너2 | U46: 37 | V46: 37 | X46: =SUBSTITUTE(S46,"(넷플릭스)","")
B47: KT | C47: 5G 초이스 베이직 (초이스선택가능) | D47: 갤럭시 S26 울트라_512G | E47: 125 | F47: 139 | H47: =SUBSTITUTE($C47, " (초이스선택가능)","") -> 5G 초이스 베이직 | P47: =SUBSTITUTE($K47, "(초이스선택가능)","") | R47: LG | S47: (넷플릭스) 플러스 플랜115 | T47: 아이폰에어_1TB | U47: 42 | V47: 137 | X47: =SUBSTITUTE(S47,"(넷플릭스)","") -> 플러스 플랜115
B48: KT | C48: 5G 초이스 베이직 (초이스선택가능) | D48: 갤럭시Z플립7 | E48: 43 | F48: 55 | H48: =SUBSTITUTE($C48, " (초이스선택가능)","") -> 5G 초이스 베이직 | P48: =SUBSTITUTE($K48, "(초이스선택가능)","") | R48: LG | T48: 키즈폰 무너2 | U48: 37 | V48: 37 | X48: =SUBSTITUTE(S48,"(넷플릭스)","")
B49: KT | C49: 5G 초이스 베이직 (초이스선택가능) | D49: 갤럭시Z폴드7 | E49: 133 | F49: 145 | H49: =SUBSTITUTE($C49, " (초이스선택가능)","") -> 5G 초이스 베이직 | P49: =SUBSTITUTE($K49, "(초이스선택가능)","") | X49: =SUBSTITUTE(S49,"(넷플릭스)","")
B50: KT | C50: 5G 초이스 베이직 (초이스선택가능) | D50: 갤럭시S25엣지 | E50: 18 | F50: 23 | H50: =SUBSTITUTE($C50, " (초이스선택가능)","") -> 5G 초이스 베이직 | P50: =SUBSTITUTE($K50, "(초이스선택가능)","") | X50: =SUBSTITUTE(S50,"(넷플릭스)","")
B51: KT | C51: 5G 초이스 베이직 (초이스선택가능) | D51: 갤럭시S25엣지(개봉) | E51: 6 | F51: 15 | H51: =SUBSTITUTE($C51, " (초이스선택가능)","") -> 5G 초이스 베이직 | P51: =SUBSTITUTE($K51, "(초이스선택가능)","") | X51: =SUBSTITUTE(S51,"(넷플릭스)","")
...

Sheet INDEX
B2: 요금제 | F2: 모델명(KT,SKT,LG순)
B3: KT 요금제 | C3: SKT 요금제 | D3: LG 요금제
B4: 5G 초이스 스페셜 | C4: 5GX 프리미엄 | D4: 플러스 플랜115 | F4: =ADMIN!D6 -> 갤럭시 S26_256G
B5: 5G 초이스 베이직 | C5: T플랜 세이브 | D5: LTE 키즈 29 | F5: =ADMIN!D7 -> 갤럭시 S26_512G
B6: 5G심플110GB | F6: =ADMIN!D8 -> 갤럭시 S26 플러스_256G
B7: Y틴 27 | F7: =ADMIN!D9 -> 갤럭시 S26 플러스_512G
B8: 5g 슬림 4GB | F8: =ADMIN!D10 -> 갤럭시 S26 울트라_256G
B9: 5G주니어 | F9: =ADMIN!D11 -> 갤럭시 S26 울트라_512G
F10: =ADMIN!D12 -> 갤럭시Z플립7
F11: =ADMIN!D13 -> 갤럭시Z폴드7
F12: =ADMIN!D14 -> 갤럭시S25엣지
F13: =ADMIN!D15 -> 갤럭시S25엣지(개봉)
F14: =ADMIN!D16 -> 갤럭시S25
F15: =ADMIN!D17 -> 갤럭시S25(개봉)
F16: =ADMIN!D18 -> 갤럭시S25+
F17: =ADMIN!D19 -> 갤럭시S25+(개봉)
F18: =ADMIN!D20 -> 갤럭시S25울트라
F19: =ADMIN!D21 -> 갤럭시S25울트라(개봉)
F20: =ADMIN!D22 -> 갤럭시 Z 플립6(개봉)
F21: =ADMIN!D23 -> 갤럭시 Z 폴드6
... F83: =ADMIN!D85 -> 0
F84: =ADMIN!L6 -> 갤럭시 S26_256G
F85: =ADMIN!L7 -> 갤럭시 S26_512G
F86: =ADMIN!L8 -> 갤럭시 S26 플러스_256G
F87: =ADMIN!L9 -> 갤럭시 S26 플러스_512G
F88: =ADMIN!L10 -> 갤럭시 S26 울트라_256G
F89: =ADMIN!L11 -> 갤럭시 S26 울트라_512G
F90: =ADMIN!L12 -> 갤럭시Z플립7
F91: =ADMIN!L13 -> 갤럭시Z폴드7
F92: =ADMIN!L14 -> 갤럭시S25엣지
F93: =ADMIN!L15 -> 갤럭시S25
F94: =ADMIN!L16 -> 갤럭시S25+
F95: =ADMIN!L17 -> 갤럭시S25울트라
... F163: =ADMIN!L85 -> 0
F164: =ADMIN!T6 -> 갤럭시 S26_256G
F165: =ADMIN!T7 -> 갤럭시 S26_512G
F166: =ADMIN!T8 -> 갤럭시 S26 플러스_256G
F167: =ADMIN!T9 -> 갤럭시 S26 플러스_512G
F168: =ADMIN!T10 -> 갤럭시 S26 울트라_256G
F169: =ADMIN!T11 -> 갤럭시 S26 울트라_512G
...

Sheet SKT
L2: =TEXT(TODAY(),"m월 d일 오늘의 특가") -> 6월 25일 오늘의 특가 | M2: ◀ 절대 삭제 금지
B3: =TEXT(TODAY(),"m월 d일 오늘의 특가") -> 6월 25일 오늘의 특가 | D3: 5GX 프리미엄 | F3: 5GX프라임 | H3: T플랜 세이브
D4: 번이 | E4: 기변 | F4: 번이 | G4: 기변 | H4: 번이 | I4: 기변
B5: 갤럭시Z플립7
B6: 갤럭시Z폴드7
B7: 갤럭시S25엣지
B8: 갤럭시S25
B9: 갤럭시S25+
B10: 갤럭시S25울트라
B11: 아이폰16_128G
B12: 아이폰16플러스_128G
B13: 아이폰16프로_128G
B14: 아이폰16프로맥스_256G
B15: 갤럭시 Z 폴드6
B16: 갤럭시 Z 플립6
... B22: 갤럭시A16
D23: {=IFERROR(INDEX(SKT번이구매가,MATCH(1,(SKT요금제=$D$3)*(SKT모델명=$B23),0)),"")} | E23: {=IFERROR(INDEX(SKT기변구매가,MATCH(1,(SKT요금제=$D$3)*(SKT모델명=$B23),0)),"")} | F23: {=IFERROR(INDEX(SKT번이구매가,MATCH(1,(SKT요금제=$F$3)*(SKT모델명=$B23),0)),"")} | G23: {=IFERROR(INDEX(SKT기변구매가,MATCH(1,(SKT요금제=$F$3)*(SKT모델명=$B23),0)),"")} | H23: {=IFERROR(INDEX(SKT번이구매가,MATCH(1,(SKT요금제=$H$3)*(SKT모델명=$B23),0)),"")} | I23: {=IFERROR(INDEX(SKT기변구매가,MATCH(1,(SKT요금제=$H$3)*(SKT모델명=$B23),0)),"")}
D24: {=IFERROR(INDEX(SKT번이구매가,MATCH(1,(SKT요금제=$D$3)*(SKT모델명=$B24),0)),"")} | E24: {=IFERROR(INDEX(SKT기변구매가,MATCH(1,(SKT요금제=$D$3)*(SKT모델명=$B24),0)),"")} | F24: {=IFERROR(INDEX(SKT번이구매가,MATCH(1,(SKT요금제=$F$3)*(SKT모델명=$B24),0)),"")} | G24: {=IFERROR(INDEX(SKT기변구매가,MATCH(1,(SKT요금제=$F$3)*(SKT모델명=$B24),0)),"")} | H24: {=IFERROR(INDEX(SKT번이구매가,MATCH(1,(SKT요금제=$H$3)*(SKT모델명=$B24),0)),"")} | I24: {=IFERROR(INDEX(SKT기변구매가,MATCH(1,(SKT요금제=$H$3)*(SKT모델명=$B24),0)),"")}
D25: {=IFERROR(INDEX(SKT번이구매가,MATCH(1,(SKT요금제=$D$3)*(SKT모델명=$B25),0)),"")} | E25: {=IFERROR(INDEX(SKT기변구매가,MATCH(1,(SKT요금제=$D$3)*(SKT모델명=$B25),0)),"")} | F25: {=IFERROR(INDEX(SKT번이구매가,MATCH(1,(SKT요금제=$F$3)*(SKT모델명=$B25),0)),"")} | G25: {=IFERROR(INDEX(SKT기변구매가,MATCH(1,(SKT요금제=$F$3)*(SKT모델명=$B25),0)),"")} | H25: {=IFERROR(INDEX(SKT번이구매가,MATCH(1,(SKT요금제=$H$3)*(SKT모델명=$B25),0)),"")} | I25: {=IFERROR(INDEX(SKT기변구매가,MATCH(1,(SKT요금제=$H$3)*(SKT모델명=$B25),0)),"")}
D26: {=IFERROR(INDEX(SKT번이구매가,MATCH(1,(SKT요금제=$D$3)*(SKT모델명=$B26),0)),"")} | E26: {=IFERROR(INDEX(SKT기변구매가,MATCH(1,(SKT요금제=$D$3)*(SKT모델명=$B26),0)),"")} | F26: {=IFERROR(INDEX(SKT번이구매가,MATCH(1,(SKT요금제=$F$3)*(SKT모델명=$B26),0)),"")} | G26: {=IFERROR(INDEX(SKT기변구매가,MATCH(1,(SKT요금제=$F$3)*(SKT모델명=$B26),0)),"")} | H26: {=IFERROR(INDEX(SKT번이구매가,MATCH(1,(SKT요금제=$H$3)*(SKT모델명=$B26),0)),"")} | I26: {=IFERROR(INDEX(SKT기변구매가,MATCH(1,(SKT요금제=$H$3)*(SKT모델명=$B26),0)),"")}
D27: {=IFERROR(INDEX(SKT번이구매가,MATCH(1,(SKT요금제=$D$3)*(SKT모델명=$B27),0)),"")} | E27: {=IFERROR(INDEX(SKT기변구매가,MATCH(1,(SKT요금제=$D$3)*(SKT모델명=$B27),0)),"")} | F27: {=IFERROR(INDEX(SKT번이구매가,MATCH(1,(SKT요금제=$F$3)*(SKT모델명=$B27),0)),"")} | G27: {=IFERROR(INDEX(SKT기변구매가,MATCH(1,(SKT요금제=$F$3)*(SKT모델명=$B27),0)),"")} | H27: {=IFERROR(INDEX(SKT번이구매가,MATCH(1,(SKT요금제=$H$3)*(SKT모델명=$B27),0)),"")} | I27: {=IFERROR(INDEX(SKT기변구매가,MATCH(1,(SKT요금제=$H$3)*(SKT모델명=$B27),0)),"")}
D28: {=IFERROR(INDEX(SKT번이구매가,MATCH(1,(SKT요금제=$D$3)*(SKT모델명=$B28),0)),"")} | E28: {=IFERROR(INDEX(SKT기변구매가,MATCH(1,(SKT요금제=$D$3)*(SKT모델명=$B28),0)),"")} | F28: {=IFERROR(INDEX(SKT번이구매가,MATCH(1,(SKT요금제=$F$3)*(SKT모델명=$B28),0)),"")} | G28: {=IFERROR(INDEX(SKT기변구매가,MATCH(1,(SKT요금제=$F$3)*(SKT모델명=$B28),0)),"")} | H28: {=IFERROR(INDEX(SKT번이구매가,MATCH(1,(SKT요금제=$H$3)*(SKT모델명=$B28),0)),"")} | I28: {=IFERROR(INDEX(SKT기변구매가,MATCH(1,(SKT요금제=$H$3)*(SKT모델명=$B28),0)),"")}
D29: {=IFERROR(INDEX(SKT번이구매가,MATCH(1,(SKT요금제=$D$3)*(SKT모델명=$B29),0)),"")} | E29: {=IFERROR(INDEX(SKT기변구매가,MATCH(1,(SKT요금제=$D$3)*(SKT모델명=$B29),0)),"")} | F29: {=IFERROR(INDEX(SKT번이구매가,MATCH(1,(SKT요금제=$F$3)*(SKT모델명=$B29),0)),"")} | G29: {=IFERROR(INDEX(SKT기변구매가,MATCH(1,(SKT요금제=$F$3)*(SKT모델명=$B29),0)),"")} | H29: {=IFERROR(INDEX(SKT번이구매가,MATCH(1,(SKT요금제=$H$3)*(SKT모델명=$B29),0)),"")} | I29: {=IFERROR(INDEX(SKT기변구매가,MATCH(1,(SKT요금제=$H$3)*(SKT모델명=$B29),0)),"")}
D30: {=IFERROR(INDEX(SKT번이구매가,MATCH(1,(SKT요금제=$D$3)*(SKT모델명=$B30),0)),"")} | E30: {=IFERROR(INDEX(SKT기변구매가,MATCH(1,(SKT요금제=$D$3)*(SKT모델명=$B30),0)),"")} | F30: {=IFERROR(INDEX(SKT번이구매가,MATCH(1,(SKT요금제=$F$3)*(SKT모델명=$B30),0)),"")} | G30: {=IFERROR(INDEX(SKT기변구매가,MATCH(1,(SKT요금제=$F$3)*(SKT모델명=$B30),0)),"")} | H30: {=IFERROR(INDEX(SKT번이구매가,MATCH(1,(SKT요금제=$H$3)*(SKT모델명=$B30),0)),"")} | I30: {=IFERROR(INDEX(SKT기변구매가,MATCH(1,(SKT요금제=$H$3)*(SKT모델명=$B30),0)),"")}
D31: {=IFERROR(INDEX(SKT번이구매가,MATCH(1,(SKT요금제=$D$3)*(SKT모델명=$B31),0)),"")} | E31: {=IFERROR(INDEX(SKT기변구매가,MATCH(1,(SKT요금제=$D$3)*(SKT모델명=$B31),0)),"")} | F31: {=IFERROR(INDEX(SKT번이구매가,MATCH(1,(SKT요금제=$F$3)*(SKT모델명=$B31),0)),"")} | G31: {=IFERROR(INDEX(SKT기변구매가,MATCH(1,(SKT요금제=$F$3)*(SKT모델명=$B31),0)),"")} | H31: {=IFERROR(INDEX(SKT번이구매가,MATCH(1,(SKT요금제=$H$3)*(SKT모델명=$B31),0)),"")} | I31: {=IFERROR(INDEX(SKT기변구매가,MATCH(1,(SKT요금제=$H$3)*(SKT모델명=$B31),0)),"")}
D32: {=IFERROR(INDEX(SKT번이구매가,MATCH(1,(SKT요금제=$D$3)*(SKT모델명=$B32),0)),"")} | E32: {=IFERROR(INDEX(SKT기변구매가,MATCH(1,(SKT요금제=$D$3)*(SKT모델명=$B32),0)),"")} | F32: {=IFERROR(INDEX(SKT번이구매가,MATCH(1,(SKT요금제=$F$3)*(SKT모델명=$B32),0)),"")} | G32: {=IFERROR(INDEX(SKT기변구매가,MATCH(1,(SKT요금제=$F$3)*(SKT모델명=$B32),0)),"")} | H32: {=IFERROR(INDEX(SKT번이구매가,MATCH(1,(SKT요금제=$H$3)*(SKT모델명=$B32),0)),"")} | I32: {=IFERROR(INDEX(SKT기변구매가,MATCH(1,(SKT요금제=$H$3)*(SKT모델명=$B32),0)),"")}
D33: {=IFERROR(INDEX(SKT번이구매가,MATCH(1,(SKT요금제=$D$3)*(SKT모델명=$B33),0)),"")} | E33: {=IFERROR(INDEX(SKT기변구매가,MATCH(1,(SKT요금제=$D$3)*(SKT모델명=$B33),0)),"")} | F33: {=IFERROR(INDEX(SKT번이구매가,MATCH(1,(SKT요금제=$F$3)*(SKT모델명=$B33),0)),"")} | G33: {=IFERROR(INDEX(SKT기변구매가,MATCH(1,(SKT요금제=$F$3)*(SKT모델명=$B33),0)),"")} | H33: {=IFERROR(INDEX(SKT번이구매가,MATCH(1,(SKT요금제=$H$3)*(SKT모델명=$B33),0)),"")} | I33: {=IFERROR(INDEX(SKT기변구매가,MATCH(1,(SKT요금제=$H$3)*(SKT모델명=$B33),0)),"")}
D34: {=IFERROR(INDEX(SKT번이구매가,MATCH(1,(SKT요금제=$D$3)*(SKT모델명=$B34),0)),"")} | E34: {=IFERROR(INDEX(SKT기변구매가,MATCH(1,(SKT요금제=$D$3)*(SKT모델명=$B34),0)),"")} | F34: {=IFERROR(INDEX(SKT번이구매가,MATCH(1,(SKT요금제=$F$3)*(SKT모델명=$B34),0)),"")} | G34: {=IFERROR(INDEX(SKT기변구매가,MATCH(1,(SKT요금제=$F$3)*(SKT모델명=$B34),0)),"")} | H34: {=IFERROR(INDEX(SKT번이구매가,MATCH(1,(SKT요금제=$H$3)*(SKT모델명=$B34),0)),"")} | I34: {=IFERROR(INDEX(SKT기변구매가,MATCH(1,(SKT요금제=$H$3)*(SKT모델명=$B34),0)),"")}
B37: {=IFERROR(INDEX(SKT번이구매가,MATCH(1,(SKT요금제=$B$5)*(SKT모델명=#REF!),0)),"")} | D37: {=IFERROR(INDEX(SKT기변구매가,MATCH(1,(SKT요금제=$B$5)*(SKT모델명=#REF!),0)),"")} | E37: {=IFERROR(INDEX(KT번이구매가,MATCH(1,(KT요금제=$E$5)*(KT모델명=#REF!),0)),"")} | F37: {=IFERROR(INDEX(KT기변구매가,MATCH(1,(KT요금제=$E$5)*(KT모델명=#REF!),0)),"")} | G37: {=IFERROR(INDEX(LG번이구매가,MATCH(1,(LG요금제=$G$5)*(LG모델명=#REF!),0)),"")} | H37: {=IFERROR(INDEX(LG기변구매가,MATCH(1,(LG요금제=$G$5)*(LG모델명=#REF!),0)),"")}
B38: 요금제 | C38: 월 요금 | D38: 유지기간 | E38: 이용량 | G38: 혜택
B39: 5GX 프리미엄 | C39: 109000 | D39: 185일 | E39: 통화/문자/데이터 무제한 영상/부가통화 300분 | G39: 넷플릭스, 디즈니+ YouTube 프리미엄 할인 등 택 1 스마트기기 2회선 이용 요금 무료
B40: 5GX 프라임 | C40: 89000 | D40: 185일 | E40: 통화/문자/데이터 무제한 영상/부가통화 300분 | G40: 넷플릭스, 디즈니+ YouTube 프리미엄 할인 등 택 1 스마트기기 2회선 이용 요금 무료
B41: T플랜 세이브 | C41: 33000 | D41: 185일 | E41: 통화/문자 무제한 데이터 1.5GB 영상/부가통화 100분 | G41: 기본 데이터 소진 후, 추가 요금 발생 가능 * 밤 지킴이 데이터 4배 * 0~7시 데이터 7% 할인
B46: 요금제 | C46: 월 요금 | D46: 유지기간 | E46: 혜택
B47: 마이스마트콜3 | C47: 3500 | D47: 95일 이상 | E47: 놓친 전화 안내 / 컬러링 / 통화 가능 통보 등
B48: T올케어 +5 | C48: 5,900~ | D48: 95일 이상 | E48: 휴대폰 보험 혜택 제공 (가입 상품별 상이)
B52: 가입유형 | C52: 인+티+번호이동 | E52: 유선 월 청구금액 | G52: 모바일+인터넷만
B53: 초고속(1G) | C53: 50만원 | E53: 월 53,900원 | G53: 40만원 | I53: 월 38,500원
B54: 초고속(500MB) | C54: 50만원 | E54: 월 48,400원 | G54: 40만원 | I54: 월 33,000원
B55: 초고속(100MB) | C55: 40만원 | E55: 월 40,700원 | G55: 30만원 | I55: 월 22,000원
...

Sheet KT
L2: =TEXT(TODAY(),"m월 d일 오늘의 특가") -> 6월 25일 오늘의 특가 | M2: ◀ 절대 삭제 금지
B3: =TEXT(TODAY(),"m월 d일 오늘의 특가") -> 6월 25일 오늘의 특가 | D3: 5G 초이스 스페셜 | F3: 5G 초이스 베이직 | H3: 5G심플110GB
D4: 번이 | E4: 기변 | F4: 번이 | G4: 기변 | H4: 번이 | I4: 기변
B5: 갤럭시Z플립7
B6: 갤럭시Z폴드7
B7: 갤럭시S25엣지
B8: 갤럭시S25
B9: 갤럭시S25+
B10: 갤럭시S25울트라
B11: 아이폰16_128G
B12: 아이폰16플러스_128G
B13: 아이폰16프로_128G
B14: 아이폰16프로맥스_256G
B15: 갤럭시 Z 폴드6
B16: 갤럭시 Z 플립6
... B24: 갤럭시S24FE
D25: {=IFERROR(INDEX(KT번이구매가,MATCH(1,(KT요금제=$D$3)*(KT모델명=$B25),0)),"")} | E25: {=IFERROR(INDEX(KT기변구매가,MATCH(1,(KT요금제=$D$3)*(KT모델명=$B25),0)),"")} | F25: {=IFERROR(INDEX(KT번이구매가,MATCH(1,(KT요금제=$F$3)*(KT모델명=$B25),0)),"")} | G25: {=IFERROR(INDEX(KT기변구매가,MATCH(1,(KT요금제=$F$3)*(KT모델명=$B25),0)),"")} | H25: {=IFERROR(INDEX(KT번이구매가,MATCH(1,(KT요금제=$H$3)*(KT모델명=$B25),0)),"")} | I25: {=IFERROR(INDEX(KT기변구매가,MATCH(1,(KT요금제=$H$3)*(KT모델명=$B25),0)),"")}
D26: {=IFERROR(INDEX(KT번이구매가,MATCH(1,(KT요금제=$D$3)*(KT모델명=$B26),0)),"")} | E26: {=IFERROR(INDEX(KT기변구매가,MATCH(1,(KT요금제=$D$3)*(KT모델명=$B26),0)),"")} | F26: {=IFERROR(INDEX(KT번이구매가,MATCH(1,(KT요금제=$F$3)*(KT모델명=$B26),0)),"")} | G26: {=IFERROR(INDEX(KT기변구매가,MATCH(1,(KT요금제=$F$3)*(KT모델명=$B26),0)),"")} | H26: {=IFERROR(INDEX(KT번이구매가,MATCH(1,(KT요금제=$H$3)*(KT모델명=$B26),0)),"")} | I26: {=IFERROR(INDEX(KT기변구매가,MATCH(1,(KT요금제=$H$3)*(KT모델명=$B26),0)),"")}
D27: {=IFERROR(INDEX(KT번이구매가,MATCH(1,(KT요금제=$D$3)*(KT모델명=$B27),0)),"")} | E27: {=IFERROR(INDEX(KT기변구매가,MATCH(1,(KT요금제=$D$3)*(KT모델명=$B27),0)),"")} | F27: {=IFERROR(INDEX(KT번이구매가,MATCH(1,(KT요금제=$F$3)*(KT모델명=$B27),0)),"")} | G27: {=IFERROR(INDEX(KT기변구매가,MATCH(1,(KT요금제=$F$3)*(KT모델명=$B27),0)),"")} | H27: {=IFERROR(INDEX(KT번이구매가,MATCH(1,(KT요금제=$H$3)*(KT모델명=$B27),0)),"")} | I27: {=IFERROR(INDEX(KT기변구매가,MATCH(1,(KT요금제=$H$3)*(KT모델명=$B27),0)),"")}
D28: {=IFERROR(INDEX(KT번이구매가,MATCH(1,(KT요금제=$D$3)*(KT모델명=$B28),0)),"")} | E28: {=IFERROR(INDEX(KT기변구매가,MATCH(1,(KT요금제=$D$3)*(KT모델명=$B28),0)),"")} | F28: {=IFERROR(INDEX(KT번이구매가,MATCH(1,(KT요금제=$F$3)*(KT모델명=$B28),0)),"")} | G28: {=IFERROR(INDEX(KT기변구매가,MATCH(1,(KT요금제=$F$3)*(KT모델명=$B28),0)),"")} | H28: {=IFERROR(INDEX(KT번이구매가,MATCH(1,(KT요금제=$H$3)*(KT모델명=$B28),0)),"")} | I28: {=IFERROR(INDEX(KT기변구매가,MATCH(1,(KT요금제=$H$3)*(KT모델명=$B28),0)),"")}
D29: {=IFERROR(INDEX(KT번이구매가,MATCH(1,(KT요금제=$D$3)*(KT모델명=$B29),0)),"")} | E29: {=IFERROR(INDEX(KT기변구매가,MATCH(1,(KT요금제=$D$3)*(KT모델명=$B29),0)),"")} | F29: {=IFERROR(INDEX(KT번이구매가,MATCH(1,(KT요금제=$F$3)*(KT모델명=$B29),0)),"")} | G29: {=IFERROR(INDEX(KT기변구매가,MATCH(1,(KT요금제=$F$3)*(KT모델명=$B29),0)),"")} | H29: {=IFERROR(INDEX(KT번이구매가,MATCH(1,(KT요금제=$H$3)*(KT모델명=$B29),0)),"")} | I29: {=IFERROR(INDEX(KT기변구매가,MATCH(1,(KT요금제=$H$3)*(KT모델명=$B29),0)),"")}
D30: {=IFERROR(INDEX(KT번이구매가,MATCH(1,(KT요금제=$D$3)*(KT모델명=$B30),0)),"")} | E30: {=IFERROR(INDEX(KT기변구매가,MATCH(1,(KT요금제=$D$3)*(KT모델명=$B30),0)),"")} | F30: {=IFERROR(INDEX(KT번이구매가,MATCH(1,(KT요금제=$F$3)*(KT모델명=$B30),0)),"")} | G30: {=IFERROR(INDEX(KT기변구매가,MATCH(1,(KT요금제=$F$3)*(KT모델명=$B30),0)),"")} | H30: {=IFERROR(INDEX(KT번이구매가,MATCH(1,(KT요금제=$H$3)*(KT모델명=$B30),0)),"")} | I30: {=IFERROR(INDEX(KT기변구매가,MATCH(1,(KT요금제=$H$3)*(KT모델명=$B30),0)),"")}
D31: {=IFERROR(INDEX(KT번이구매가,MATCH(1,(KT요금제=$D$3)*(KT모델명=$B31),0)),"")} | E31: {=IFERROR(INDEX(KT기변구매가,MATCH(1,(KT요금제=$D$3)*(KT모델명=$B31),0)),"")} | F31: {=IFERROR(INDEX(KT번이구매가,MATCH(1,(KT요금제=$F$3)*(KT모델명=$B31),0)),"")} | G31: {=IFERROR(INDEX(KT기변구매가,MATCH(1,(KT요금제=$F$3)*(KT모델명=$B31),0)),"")} | H31: {=IFERROR(INDEX(KT번이구매가,MATCH(1,(KT요금제=$H$3)*(KT모델명=$B31),0)),"")} | I31: {=IFERROR(INDEX(KT기변구매가,MATCH(1,(KT요금제=$H$3)*(KT모델명=$B31),0)),"")}
D32: {=IFERROR(INDEX(KT번이구매가,MATCH(1,(KT요금제=$D$3)*(KT모델명=$B32),0)),"")} | E32: {=IFERROR(INDEX(KT기변구매가,MATCH(1,(KT요금제=$D$3)*(KT모델명=$B32),0)),"")} | F32: {=IFERROR(INDEX(KT번이구매가,MATCH(1,(KT요금제=$F$3)*(KT모델명=$B32),0)),"")} | G32: {=IFERROR(INDEX(KT기변구매가,MATCH(1,(KT요금제=$F$3)*(KT모델명=$B32),0)),"")} | H32: {=IFERROR(INDEX(KT번이구매가,MATCH(1,(KT요금제=$H$3)*(KT모델명=$B32),0)),"")} | I32: {=IFERROR(INDEX(KT기변구매가,MATCH(1,(KT요금제=$H$3)*(KT모델명=$B32),0)),"")}
D33: {=IFERROR(INDEX(KT번이구매가,MATCH(1,(KT요금제=$D$3)*(KT모델명=$B33),0)),"")} | E33: {=IFERROR(INDEX(KT기변구매가,MATCH(1,(KT요금제=$D$3)*(KT모델명=$B33),0)),"")} | F33: {=IFERROR(INDEX(KT번이구매가,MATCH(1,(KT요금제=$F$3)*(KT모델명=$B33),0)),"")} | G33: {=IFERROR(INDEX(KT기변구매가,MATCH(1,(KT요금제=$F$3)*(KT모델명=$B33),0)),"")} | H33: {=IFERROR(INDEX(KT번이구매가,MATCH(1,(KT요금제=$H$3)*(KT모델명=$B33),0)),"")} | I33: {=IFERROR(INDEX(KT기변구매가,MATCH(1,(KT요금제=$H$3)*(KT모델명=$B33),0)),"")}
B36: {=IFERROR(INDEX(SKT번이구매가,MATCH(1,(SKT요금제=$B$5)*(SKT모델명=#REF!),0)),"")} | D36: {=IFERROR(INDEX(SKT기변구매가,MATCH(1,(SKT요금제=$B$5)*(SKT모델명=#REF!),0)),"")} | E36: {=IFERROR(INDEX(KT번이구매가,MATCH(1,(KT요금제=$E$5)*(KT모델명=#REF!),0)),"")} | F36: {=IFERROR(INDEX(KT기변구매가,MATCH(1,(KT요금제=$E$5)*(KT모델명=#REF!),0)),"")} | G36: {=IFERROR(INDEX(LG번이구매가,MATCH(1,(LG요금제=$G$5)*(LG모델명=#REF!),0)),"")} | H36: {=IFERROR(INDEX(LG기변구매가,MATCH(1,(LG요금제=$G$5)*(LG모델명=#REF!),0)),"")}
B37: 요금제 | C37: 월 요금 | D37: 유지기간 | E37: 이용량 | G37: 혜택
B38: 5G 초이스 스페셜 | C38: 110000 | D38: 185일 | E38: 통화/문자/데이터 무제한 영상/부가통화 300분 | G38: 넷플릭스, 디즈니+ YouTube 프리미엄 할인 등 택 1
B39: 5G 초이스 베이직 | C39: 90000 | D39: 185일 | E39: 통화/문자/데이터 무제한 영상/부가통화 300분 | G39: 넷플릭스, 디즈니+ YouTube 프리미엄 할인 등 택 1
B40: 5G 심플 110GB | C40: 69000 | D40: 185일 | E40: 통화/문자 무제한 데이터 110GB + 5Mbps 영상/부가통화 300분 | G40: Y덤 기본 데이터 2배 제공 만 34세 이하
B45: 요금제 | C45: 월 요금 | D45: 유지기간 | E45: 혜택
B46: 필수팩 L1 | C46: 9900 | D46: M+3개월 | E46: 지니뮤직 + 블라이스 셀렉트 + V컬러링, 듀얼번호 Lite, 캐치콜, 통화가능알리미
B47: 필수팩 L2 | C47: 9900 | D47: M+3개월 | E47: 지니뮤직 + 블라이스 셀렉트 + V컬러링, 듀얼번호 Lite, 캐치콜, 통화가능알리미
B48: 필수팩 L3 | C48: 9900 | D48: M+3개월 | E48: 지니뮤직 + 밀리의 서재 + V컬러링, 캐치콜, 통화가능알리미
B49: 필수팩 M1 | C49: 6900 | D49: M+3개월 | E49: V컬러링, 듀얼번호 Lite, 캐치콜, 통화가능알리미
B50: KT 365 폰케어 | C50: 5,900 ~ | D50: M+1개월 | E50: 휴대폰 보험 혜택 제공 하단 공식 홈페이지 링크 참고
B54: 가입유형 | C54: 인터넷+TV | D54: 인+티+번호이동 | F54: 인+티+기기변경 | H54: 인+티 월 청구금액
B55: 인터넷 에센스(1G) 지니 TV 에센스 | C55: 50만원 +10(상품권) | D55: 82만원 + 10(상품권) | F55: 75만원 + 10(상품권) | H55: 58850
B56: 인터넷 베이직(500MB) 지니 TV 에센스 | C56: 35만원 +7(상품권) | D56: 65만원 + 7(상품권) | F56: 60만원 + 7(상품권) | H56: 54450
B57: 인터넷 베이직(500MB) TV 베이직 | C57: 20만원 +6(상품권) | D57: 30만원 + 6(상품권) | F57: 30만원 + 6(상품권) | H57: 50050 | K57: ◀ 예시입니다 안에 정책은 수정해야함
...

Sheet U+
J2: =TEXT(TODAY(),"m월 d일 오늘의 특가") -> 6월 25일 오늘의 특가 | K2: ◀ 절대 삭제 금지
B3: =TEXT(TODAY(),"m월 d일 오늘의 특가") -> 6월 25일 오늘의 특가 | D3: 5G 프리미어 슈퍼 | F3: LTE 키즈 29
D4: 번이 | E4: 기변 | F4: 번이 | G4: 기변
B5: 갤럭시Z플립7
B6: 갤럭시Z폴드7
B7: 갤럭시S25
B8: 갤럭시S25+
B9: 갤럭시S25울트라
B10: 아이폰16_128G
B11: 아이폰16플러스_128G
B12: 아이폰16프로_128G
B13: 아이폰16프로맥스_256G
B14: 갤럭시 Z 폴드6
B15: 갤럭시 Z 플립6
B16: 갤럭시Z폴드5
... B20: 갤럭시S24울트라
B21: U+키즈폰무너에디션 | D21: {=IFERROR(INDEX(LG번이구매가,MATCH(1,(LG요금제=$D$3)*(LG모델명=$B21),0)),"")} | E21: {=IFERROR(INDEX(LG기변구매가,MATCH(1,(LG요금제=$D$3)*(LG모델명=$B21),0)),"")} | F21: {=IFERROR(INDEX(LG번이구매가,MATCH(1,(LG요금제=$F$3)*(LG모델명=$B21),0)),"")} | G21: {=IFERROR(INDEX(LG기변구매가,MATCH(1,(LG요금제=$F$3)*(LG모델명=$B21),0)),"")}
D22: {=IFERROR(INDEX(LG번이구매가,MATCH(1,(LG요금제=$D$3)*(LG모델명=$B22),0)),"")} | E22: {=IFERROR(INDEX(LG기변구매가,MATCH(1,(LG요금제=$D$3)*(LG모델명=$B22),0)),"")} | F22: {=IFERROR(INDEX(LG번이구매가,MATCH(1,(LG요금제=$F$3)*(LG모델명=$B22),0)),"")} | G22: {=IFERROR(INDEX(LG기변구매가,MATCH(1,(LG요금제=$F$3)*(LG모델명=$B22),0)),"")}
D23: {=IFERROR(INDEX(LG번이구매가,MATCH(1,(LG요금제=$D$3)*(LG모델명=$B23),0)),"")} | E23: {=IFERROR(INDEX(LG기변구매가,MATCH(1,(LG요금제=$D$3)*(LG모델명=$B23),0)),"")} | F23: {=IFERROR(INDEX(LG번이구매가,MATCH(1,(LG요금제=$F$3)*(LG모델명=$B23),0)),"")} | G23: {=IFERROR(INDEX(LG기변구매가,MATCH(1,(LG요금제=$F$3)*(LG모델명=$B23),0)),"")}
D24: {=IFERROR(INDEX(LG번이구매가,MATCH(1,(LG요금제=$D$3)*(LG모델명=$B24),0)),"")} | E24: {=IFERROR(INDEX(LG기변구매가,MATCH(1,(LG요금제=$D$3)*(LG모델명=$B24),0)),"")} | F24: {=IFERROR(INDEX(LG번이구매가,MATCH(1,(LG요금제=$F$3)*(LG모델명=$B24),0)),"")} | G24: {=IFERROR(INDEX(LG기변구매가,MATCH(1,(LG요금제=$F$3)*(LG모델명=$B24),0)),"")}
D25: {=IFERROR(INDEX(LG번이구매가,MATCH(1,(LG요금제=$D$3)*(LG모델명=$B25),0)),"")} | E25: {=IFERROR(INDEX(LG기변구매가,MATCH(1,(LG요금제=$D$3)*(LG모델명=$B25),0)),"")} | F25: {=IFERROR(INDEX(LG번이구매가,MATCH(1,(LG요금제=$F$3)*(LG모델명=$B25),0)),"")} | G25: {=IFERROR(INDEX(LG기변구매가,MATCH(1,(LG요금제=$F$3)*(LG모델명=$B25),0)),"")}
D26: {=IFERROR(INDEX(LG번이구매가,MATCH(1,(LG요금제=$D$3)*(LG모델명=$B26),0)),"")} | E26: {=IFERROR(INDEX(LG기변구매가,MATCH(1,(LG요금제=$D$3)*(LG모델명=$B26),0)),"")} | F26: {=IFERROR(INDEX(LG번이구매가,MATCH(1,(LG요금제=$F$3)*(LG모델명=$B26),0)),"")} | G26: {=IFERROR(INDEX(LG기변구매가,MATCH(1,(LG요금제=$F$3)*(LG모델명=$B26),0)),"")}
D27: {=IFERROR(INDEX(LG번이구매가,MATCH(1,(LG요금제=$D$3)*(LG모델명=$B27),0)),"")} | E27: {=IFERROR(INDEX(LG기변구매가,MATCH(1,(LG요금제=$D$3)*(LG모델명=$B27),0)),"")} | F27: {=IFERROR(INDEX(LG번이구매가,MATCH(1,(LG요금제=$F$3)*(LG모델명=$B27),0)),"")} | G27: {=IFERROR(INDEX(LG기변구매가,MATCH(1,(LG요금제=$F$3)*(LG모델명=$B27),0)),"")}
D28: {=IFERROR(INDEX(LG번이구매가,MATCH(1,(LG요금제=$D$3)*(LG모델명=$B28),0)),"")} | E28: {=IFERROR(INDEX(LG기변구매가,MATCH(1,(LG요금제=$D$3)*(LG모델명=$B28),0)),"")} | F28: {=IFERROR(INDEX(LG번이구매가,MATCH(1,(LG요금제=$F$3)*(LG모델명=$B28),0)),"")} | G28: {=IFERROR(INDEX(LG기변구매가,MATCH(1,(LG요금제=$F$3)*(LG모델명=$B28),0)),"")}
D29: {=IFERROR(INDEX(LG번이구매가,MATCH(1,(LG요금제=$D$3)*(LG모델명=$B29),0)),"")} | E29: {=IFERROR(INDEX(LG기변구매가,MATCH(1,(LG요금제=$D$3)*(LG모델명=$B29),0)),"")} | F29: {=IFERROR(INDEX(LG번이구매가,MATCH(1,(LG요금제=$F$3)*(LG모델명=$B29),0)),"")} | G29: {=IFERROR(INDEX(LG기변구매가,MATCH(1,(LG요금제=$F$3)*(LG모델명=$B29),0)),"")}
D30: {=IFERROR(INDEX(LG번이구매가,MATCH(1,(LG요금제=$D$3)*(LG모델명=$B30),0)),"")} | E30: {=IFERROR(INDEX(LG기변구매가,MATCH(1,(LG요금제=$D$3)*(LG모델명=$B30),0)),"")} | F30: {=IFERROR(INDEX(LG번이구매가,MATCH(1,(LG요금제=$F$3)*(LG모델명=$B30),0)),"")} | G30: {=IFERROR(INDEX(LG기변구매가,MATCH(1,(LG요금제=$F$3)*(LG모델명=$B30),0)),"")}
D31: {=IFERROR(INDEX(LG번이구매가,MATCH(1,(LG요금제=$D$3)*(LG모델명=$B31),0)),"")} | E31: {=IFERROR(INDEX(LG기변구매가,MATCH(1,(LG요금제=$D$3)*(LG모델명=$B31),0)),"")} | F31: {=IFERROR(INDEX(LG번이구매가,MATCH(1,(LG요금제=$F$3)*(LG모델명=$B31),0)),"")} | G31: {=IFERROR(INDEX(LG기변구매가,MATCH(1,(LG요금제=$F$3)*(LG모델명=$B31),0)),"")}
D32: {=IFERROR(INDEX(LG번이구매가,MATCH(1,(LG요금제=$D$3)*(LG모델명=$B32),0)),"")} | E32: {=IFERROR(INDEX(LG기변구매가,MATCH(1,(LG요금제=$D$3)*(LG모델명=$B32),0)),"")} | F32: {=IFERROR(INDEX(LG번이구매가,MATCH(1,(LG요금제=$F$3)*(LG모델명=$B32),0)),"")} | G32: {=IFERROR(INDEX(LG기변구매가,MATCH(1,(LG요금제=$F$3)*(LG모델명=$B32),0)),"")}
D33: {=IFERROR(INDEX(LG번이구매가,MATCH(1,(LG요금제=$D$3)*(LG모델명=$B33),0)),"")} | E33: {=IFERROR(INDEX(LG기변구매가,MATCH(1,(LG요금제=$D$3)*(LG모델명=$B33),0)),"")} | F33: {=IFERROR(INDEX(LG번이구매가,MATCH(1,(LG요금제=$F$3)*(LG모델명=$B33),0)),"")} | G33: {=IFERROR(INDEX(LG기변구매가,MATCH(1,(LG요금제=$F$3)*(LG모델명=$B33),0)),"")}
... D36: {=IFERROR(INDEX(LG번이구매가,MATCH(1,(LG요금제=$D$3)*(LG모델명=$B36),0)),"")} | E36: {=IFERROR(INDEX(LG기변구매가,MATCH(1,(LG요금제=$D$3)*(LG모델명=$B36),0)),"")} | F36: {=IFERROR(INDEX(LG번이구매가,MATCH(1,(LG요금제=$F$3)*(LG모델명=$B36),0)),"")} | G36: {=IFERROR(INDEX(LG기변구매가,MATCH(1,(LG요금제=$F$3)*(LG모델명=$B36),0)),"")}
B39: {=IFERROR(INDEX(SKT번이구매가,MATCH(1,(SKT요금제=$B$7)*(SKT모델명=#REF!),0)),"")} | D39: {=IFERROR(INDEX(SKT기변구매가,MATCH(1,(SKT요금제=$B$7)*(SKT모델명=#REF!),0)),"")} | E39: {=IFERROR(INDEX(KT번이구매가,MATCH(1,(KT요금제=$E$7)*(KT모델명=#REF!),0)),"")} | F39: {=IFERROR(INDEX(KT기변구매가,MATCH(1,(KT요금제=$E$7)*(KT모델명=#REF!),0)),"")} | G39: {=IFERROR(INDEX(LG번이구매가,MATCH(1,(LG요금제=$G$7)*(LG모델명=#REF!),0)),"")}
B40: 요금제 | C40: 월 요금 | D40: 유지기간 | E40: 이용량 | G40: 혜택
B41: 프리미어슈퍼 | C41: 115000 | D41: 185일 | E41: 통화/문자/데이터 무제한 영상/부가통화 300분 | G41: 넷플릭스, 디즈니+ YouTube 프리미엄 할인 등 택 1
B42: 5G 초이스 베이직 | C42: 90000 | D42: 185일 | E42: 통화/문자/데이터 무제한 영상/부가통화 300분 | G42: 넷플릭스, 디즈니+ YouTube 프리미엄 할인 등 택 1
B43: 5G 심플 110GB | C43: 69000 | D43: 185일 | E43: 통화/문자 무제한 데이터 110GB + 5Mbps 영상/부가통화 300분 | G43: Y덤 기본 데이터 2배 제공 만 34세 이하
B48: 요금제 | C48: 월 요금 | D48: 유지기간 | E48: 혜택
B49: 폰안심패스(보험) | C49: 상품마다 상이 | D49: 95일 이상 | E49: 분실 or 파손 보험혜택
B50: 뮤직벨링 | C50: 8800 | D50: 95일 이상 | E50: 통화 연결음 혜택 + V컬러링 등
B54: 인터넷+TV | C54: 인+티+번호이동 | E54: 인+티+기변 | G54: 월 청구금액
B55: 모바일+ 프리미엄안심보상(1G) +TV(프리미엄VOD) | C55: 80만원 | E55: 55만원 | G55: 월 62,700원
...
